Workbook

Sheet Dashboard
A1: 📊 Life Gamification Dashboard - 2026-2027
A3: Monthly Summary
A4: Month | B4: Days Logged | C4: Total Score | D4: Avg Daily | E4: Prayer Pts | F4: Family Pts | G4: Habit Pts
A5: Jan 2026 | B5: =COUNTA('Jan 2026'!A4:A34) | C5: =SUM('Jan 2026'!AR4:AR34) | D5: =IF(B5>0,ROUND(C5/B5,0),0) | E5: =SUM('Jan 2026'!AM4:AM34) | F5: =SUM('Jan 2026'!AP4:AP34) | G5: =SUM('Jan 2026'!AQ4:AQ34)
A6: Feb 2026 | B6: =COUNTA('Feb 2026'!A4:A34) | C6: =SUM('Feb 2026'!AR4:AR34) | D6: =IF(B6>0,ROUND(C6/B6,0),0) | E6: =SUM('Feb 2026'!AM4:AM34) | F6: =SUM('Feb 2026'!AP4:AP34) | G6: =SUM('Feb 2026'!AQ4:AQ34)
A7: Mar 2026 | B7: =COUNTA('Mar 2026'!A4:A34) | C7: =SUM('Mar 2026'!AR4:AR34) | D7: =IF(B7>0,ROUND(C7/B7,0),0) | E7: =SUM('Mar 2026'!AM4:AM34) | F7: =SUM('Mar 2026'!AP4:AP34) | G7: =SUM('Mar 2026'!AQ4:AQ34)
A8: Apr 2026 | B8: =COUNTA('Apr 2026'!A4:A34) | C8: =SUM('Apr 2026'!AR4:AR34) | D8: =IF(B8>0,ROUND(C8/B8,0),0) | E8: =SUM('Apr 2026'!AM4:AM34) | F8: =SUM('Apr 2026'!AP4:AP34) | G8: =SUM('Apr 2026'!AQ4:AQ34)
A9: May 2026 | B9: =COUNTA('May 2026'!A4:A34) | C9: =SUM('May 2026'!AR4:AR34) | D9: =IF(B9>0,ROUND(C9/B9,0),0) | E9: =SUM('May 2026'!AM4:AM34) | F9: =SUM('May 2026'!AP4:AP34) | G9: =SUM('May 2026'!AQ4:AQ34)
A10: Jun 2026 | B10: =COUNTA('Jun 2026'!A4:A34) | C10: =SUM('Jun 2026'!AR4:AR34) | D10: =IF(B10>0,ROUND(C10/B10,0),0) | E10: =SUM('Jun 2026'!AM4:AM34) | F10: =SUM('Jun 2026'!AP4:AP34) | G10: =SUM('Jun 2026'!AQ4:AQ34)
A11: Jul 2026 | B11: =COUNTA('Jul 2026'!A4:A34) | C11: =SUM('Jul 2026'!AR4:AR34) | D11: =IF(B11>0,ROUND(C11/B11,0),0) | E11: =SUM('Jul 2026'!AM4:AM34) | F11: =SUM('Jul 2026'!AP4:AP34) | G11: =SUM('Jul 2026'!AQ4:AQ34)
A12: Aug 2026 | B12: =COUNTA('Aug 2026'!A4:A34) | C12: =SUM('Aug 2026'!AR4:AR34) | D12: =IF(B12>0,ROUND(C12/B12,0),0) | E12: =SUM('Aug 2026'!AM4:AM34) | F12: =SUM('Aug 2026'!AP4:AP34) | G12: =SUM('Aug 2026'!AQ4:AQ34)
A13: Sep 2026 | B13: =COUNTA('Sep 2026'!A4:A34) | C13: =SUM('Sep 2026'!AR4:AR34) | D13: =IF(B13>0,ROUND(C13/B13,0),0) | E13: =SUM('Sep 2026'!AM4:AM34) | F13: =SUM('Sep 2026'!AP4:AP34) | G13: =SUM('Sep 2026'!AQ4:AQ34)
A14: Oct 2026 | B14: =COUNTA('Oct 2026'!A4:A34) | C14: =SUM('Oct 2026'!AR4:AR34) | D14: =IF(B14>0,ROUND(C14/B14,0),0) | E14: =SUM('Oct 2026'!AM4:AM34) | F14: =SUM('Oct 2026'!AP4:AP34) | G14: =SUM('Oct 2026'!AQ4:AQ34)
A15: Nov 2026 | B15: =COUNTA('Nov 2026'!A4:A34) | C15: =SUM('Nov 2026'!AR4:AR34) | D15: =IF(B15>0,ROUND(C15/B15,0),0) | E15: =SUM('Nov 2026'!AM4:AM34) | F15: =SUM('Nov 2026'!AP4:AP34) | G15: =SUM('Nov 2026'!AQ4:AQ34)
A16: Dec 2026 | B16: =COUNTA('Dec 2026'!A4:A34) | C16: =SUM('Dec 2026'!AR4:AR34) | D16: =IF(B16>0,ROUND(C16/B16,0),0) | E16: =SUM('Dec 2026'!AM4:AM34) | F16: =SUM('Dec 2026'!AP4:AP34) | G16: =SUM('Dec 2026'!AQ4:AQ34)
A17: Jan 2027 | B17: =COUNTA('Jan 2027'!A4:A34) | C17: =SUM('Jan 2027'!AR4:AR34) | D17: =IF(B17>0,ROUND(C17/B17,0),0) | E17: =SUM('Jan 2027'!AM4:AM34) | F17: =SUM('Jan 2027'!AP4:AP34) | G17: =SUM('Jan 2027'!AQ4:AQ34)
A18: Feb 2027 | B18: =COUNTA('Feb 2027'!A4:A34) | C18: =SUM('Feb 2027'!AR4:AR34) | D18: =IF(B18>0,ROUND(C18/B18,0),0) | E18: =SUM('Feb 2027'!AM4:AM34) | F18: =SUM('Feb 2027'!AP4:AP34) | G18: =SUM('Feb 2027'!AQ4:AQ34)
A19: Mar 2027 | B19: =COUNTA('Mar 2027'!A4:A34) | C19: =SUM('Mar 2027'!AR4:AR34) | D19: =IF(B19>0,ROUND(C19/B19,0),0) | E19: =SUM('Mar 2027'!AM4:AM34) | F19: =SUM('Mar 2027'!AP4:AP34) | G19: =SUM('Mar 2027'!AQ4:AQ34)
A20: Apr 2027 | B20: =COUNTA('Apr 2027'!A4:A34) | C20: =SUM('Apr 2027'!AR4:AR34) | D20: =IF(B20>0,ROUND(C20/B20,0),0) | E20: =SUM('Apr 2027'!AM4:AM34) | F20: =SUM('Apr 2027'!AP4:AP34) | G20: =SUM('Apr 2027'!AQ4:AQ34)
A21: May 2027 | B21: =COUNTA('May 2027'!A4:A34) | C21: =SUM('May 2027'!AR4:AR34) | D21: =IF(B21>0,ROUND(C21/B21,0),0) | E21: =SUM('May 2027'!AM4:AM34) | F21: =SUM('May 2027'!AP4:AP34) | G21: =SUM('May 2027'!AQ4:AQ34)
A22: Jun 2027 | B22: =COUNTA('Jun 2027'!A4:A34) | C22: =SUM('Jun 2027'!AR4:AR34) | D22: =IF(B22>0,ROUND(C22/B22,0),0) | E22: =SUM('Jun 2027'!AM4:AM34) | F22: =SUM('Jun 2027'!AP4:AP34) | G22: =SUM('Jun 2027'!AQ4:AQ34)
A23: Jul 2027 | B23: =COUNTA('Jul 2027'!A4:A34) | C23: =SUM('Jul 2027'!AR4:AR34) | D23: =IF(B23>0,ROUND(C23/B23,0),0) | E23: =SUM('Jul 2027'!AM4:AM34) | F23: =SUM('Jul 2027'!AP4:AP34) | G23: =SUM('Jul 2027'!AQ4:AQ34)
A24: Aug 2027 | B24: =COUNTA('Aug 2027'!A4:A34) | C24: =SUM('Aug 2027'!AR4:AR34) | D24: =IF(B24>0,ROUND(C24/B24,0),0) | E24: =SUM('Aug 2027'!AM4:AM34) | F24: =SUM('Aug 2027'!AP4:AP34) | G24: =SUM('Aug 2027'!AQ4:AQ34)
A25: Sep 2027 | B25: =COUNTA('Sep 2027'!A4:A34) | C25: =SUM('Sep 2027'!AR4:AR34) | D25: =IF(B25>0,ROUND(C25/B25,0),0) | E25: =SUM('Sep 2027'!AM4:AM34) | F25: =SUM('Sep 2027'!AP4:AP34) | G25: =SUM('Sep 2027'!AQ4:AQ34)
A26: Oct 2027 | B26: =COUNTA('Oct 2027'!A4:A34) | C26: =SUM('Oct 2027'!AR4:AR34) | D26: =IF(B26>0,ROUND(C26/B26,0),0) | E26: =SUM('Oct 2027'!AM4:AM34) | F26: =SUM('Oct 2027'!AP4:AP34) | G26: =SUM('Oct 2027'!AQ4:AQ34)
A27: Nov 2027 | B27: =COUNTA('Nov 2027'!A4:A34) | C27: =SUM('Nov 2027'!AR4:AR34) | D27: =IF(B27>0,ROUND(C27/B27,0),0) | E27: =SUM('Nov 2027'!AM4:AM34) | F27: =SUM('Nov 2027'!AP4:AP34) | G27: =SUM('Nov 2027'!AQ4:AQ34)
A28: Dec 2027 | B28: =COUNTA('Dec 2027'!A4:A34) | C28: =SUM('Dec 2027'!AR4:AR34) | D28: =IF(B28>0,ROUND(C28/B28,0),0) | E28: =SUM('Dec 2027'!AM4:AM34) | F28: =SUM('Dec 2027'!AP4:AP34) | G28: =SUM('Dec 2027'!AQ4:AQ34)
A29: 2026 TOTAL | B29: =SUM(B5:B16) | C29: =SUM(C5:C16) | D29: =IF(B29>0,ROUND(C29/B29,0),0) | E29: =SUM(E5:E16) | F29: =SUM(F5:F16) | G29: =SUM(G5:G16)
A30: 2027 TOTAL | B30: =SUM(B17:B28) | C30: =SUM(C17:C28) | D30: =IF(B30>0,ROUND(C30/B30,0),0) | E30: =SUM(E17:E28) | F30: =SUM(F17:F28) | G30: =SUM(G17:G28)
A31: GRAND TOTAL | B31: =SUM(B5:B28) | C31: =SUM(C5:C28) | D31: =IF(B31>0,ROUND(C31/B31,0),0) | E31: =SUM(E5:E28) | F31: =SUM(F5:F28) | G31: =SUM(G5:G28)
A33: 🏆 Personal Bests
A34: Best Day Score | B34: =MAX('Jan 2026'!AR4:AR34,'Feb 2026'!AR4:AR34,'Mar 2026'!AR4:AR34,'Apr 2026'!AR4:AR34,'May 2026'!AR4:AR34,'Jun 2026'!AR4:AR34,'Jul 2026'!AR4:AR34,'Aug 2026'!AR4:AR34,'Sep 2026'!AR4:AR34,'Oct 2026'!AR4:AR34,'Nov 2026'!AR4:AR34,'Dec 2026'!AR4:AR34,'Jan 2027'!AR4:AR34,'Feb 2027'!AR4:AR34,'Mar 2027'!AR4:AR34,'Apr 2027'!AR4:AR34,'May 2027'!AR4:AR34,'Jun 2027'!AR4:AR34,'Jul 2027'!AR4:AR34,'Aug 2027'!AR4:AR34,'Sep 2027'!AR4:AR34,'Oct 2027'!AR4:AR34,'Nov 2027'!AR4:AR34,'Dec 2027'!AR4:AR34)
A35: Best Prayer Day | B35: =MAX('Jan 2026'!AM4:AM34,'Feb 2026'!AM4:AM34,'Mar 2026'!AM4:AM34,'Apr 2026'!AM4:AM34,'May 2026'!AM4:AM34,'Jun 2026'!AM4:AM34,'Jul 2026'!AM4:AM34,'Aug 2026'!AM4:AM34,'Sep 2026'!AM4:AM34,'Oct 2026'!AM4:AM34,'Nov 2026'!AM4:AM34,'Dec 2026'!AM4:AM34,'Jan 2027'!AM4:AM34,'Feb 2027'!AM4:AM34,'Mar 2027'!AM4:AM34,'Apr 2027'!AM4:AM34,'May 2027'!AM4:AM34,'Jun 2027'!AM4:AM34,'Jul 2027'!AM4:AM34,'Aug 2027'!AM4:AM34,'Sep 2027'!AM4:AM34,'Oct 2027'!AM4:AM34,'Nov 2027'!AM4:AM34,'Dec 2027'!AM4:AM34)
A36: Best Family Day | B36: =MAX('Jan 2026'!AP4:AP34,'Feb 2026'!AP4:AP34,'Mar 2026'!AP4:AP34,'Apr 2026'!AP4:AP34,'May 2026'!AP4:AP34,'Jun 2026'!AP4:AP34,'Jul 2026'!AP4:AP34,'Aug 2026'!AP4:AP34,'Sep 2026'!AP4:AP34,'Oct 2026'!AP4:AP34,'Nov 2026'!AP4:AP34,'Dec 2026'!AP4:AP34,'Jan 2027'!AP4:AP34,'Feb 2027'!AP4:AP34,'Mar 2027'!AP4:AP34,'Apr 2027'!AP4:AP34,'May 2027'!AP4:AP34,'Jun 2027'!AP4:AP34,'Jul 2027'!AP4:AP34,'Aug 2027'!AP4:AP34,'Sep 2027'!AP4:AP34,'Oct 2027'!AP4:AP34,'Nov 2027'!AP4:AP34,'Dec 2027'!AP4:AP34)
A38: ⚙️ Scoring Weights Reference
A40: Family Check-in Weights:
A41: 👩 Mom | B41: 5 pts
A42: 👨 Dad | B42: 5 pts
A43: 👧 Jana | B43: 5 pts
A44: 👶 Tia | B44: 5 pts
...

Sheet Jan 2026
A1: Info | C1: 🕌 Prayers | I1: 💉 Glucose | O1: ⏱️ Whoop Age | AA1: 👨‍👩‍👧‍👦 Family | AG1: ✨ Habits | AM1: 📊 Scores
A2: Day | B2: Date | C2: Fajr | D2: Dhuhr | E2: Asr | F2: Maghrib | G2: Isha | H2: 📖 Quran | I2: Avg | J2: TIR% | K2: CV% | L2: Hypos | M2: Insulin | N2: NoP | O2: Sleep | P2: Consist | Q2: RHR | R2: HRV | S2: VO2 | T2: Steps | U2: Zone1-3 | V2: Zone4-5 | W2: Strength | X2: Recovery | Y2: Strain | Z2: Age | AA2: 👩 Mom | AB2: 👨 Dad | AC2: 👧 Jana | AD2: 👶 Tia | AE2: 👦 Ahmed | AF2: 👩‍🦱 Eman | AG2: 🏋️ | AH2: 📚 | AI2: 🧘 | AJ2: 💧 | AK2: 💊 | AL2: 🦷 | AM2: Prayer | AN2: Health | AO2: Whoop | AP2: Family | AQ2: Habit | AR2: TOTAL
AA3: (5 pts) | AB3: (5 pts) | AC3: (5 pts) | AD3: (5 pts) | AE3: (5 pts) | AF3: (5 pts)
A4: 1 | B4: Thu | C4: 1 | D4: 1 | E4: 1 | F4: 0.1 | G4: 0.1 | AM4: =SUMPRODUCT((TRUNC(C4:G4))*10)+SUMPRODUCT(ROUND((C4:G4-TRUNC(C4:G4))*10,0)*5)+IF(H4="",0,H4*10) | AN4: =IF(AND(I4>=70,I4<=140),20,IF(AND(I4>140,I4<=180),10,0))+IF(J4>=70,15,IF(J4>=50,8,0))+IF(AND(K4>0,K4<=30),10,IF(AND(K4>30,K4<=50),5,0))+IF(L4=0,10,0)+IF(M4>0,5,0)+IF(N4<>"",N4*2,0) | AO4: =IF(AND(O4>=7,O4<=8),15,IF(AND(O4>=6,O4<7),8,IF(O4>8,10,0)))+IF(P4>=80,10,IF(P4>=70,6,IF(P4>=60,3,0)))+IF(Q4<=60,15,IF(Q4<=70,10,IF(Q4<=80,5,0)))+IF(R4>=50,10,IF(R4>=40,6,IF(R4>=30,3,0)))+IF(S4>=45,15,IF(S4>=40,12,IF(S4>=35,8,IF(S4>=30,4,0))))+IF(T4>=10000,10,IF(T4>=8000,7,IF(T4>=6000,4,0)))+IF(U4<>"",U4*5,0)+IF(V4<>"",V4*10,0)+IF(W4<>"",W4*8,0)+IF(X4>=66,10,IF(X4>=50,6,IF(X4>=33,3,0))) | AP4: =IF(AA4=1,5,0)+IF(AB4=1,5,0)+IF(AC4=1,5,0)+IF(AD4=1,5,0)+IF(AE4=1,5,0)+IF(AF4=1,5,0) | AQ4: =IF(AG4<>"",AG4*8,0)+IF(AH4<>"",AH4*5,0)+IF(AI4<>"",AI4*10,0)+IF(AJ4<>"",AJ4*3,0)+IF(AK4=1,5,0)+IF(AL4<>"",AL4*5,0) | AR4: =AM4+AN4+AO4+AP4+AQ4
A5: 2 | B5: Fri | C5: 1 | D5: 1 | E5: 1 | F5: 1 | G5: 1 | AA5: 1 | AB5: 1 | AM5: =SUMPRODUCT((TRUNC(C5:G5))*10)+SUMPRODUCT(ROUND((C5:G5-TRUNC(C5:G5))*10,0)*5)+IF(H5="",0,H5*10) | AN5: =IF(AND(I5>=70,I5<=140),20,IF(AND(I5>140,I5<=180),10,0))+IF(J5>=70,15,IF(J5>=50,8,0))+IF(AND(K5>0,K5<=30),10,IF(AND(K5>30,K5<=50),5,0))+IF(L5=0,10,0)+IF(M5>0,5,0)+IF(N5<>"",N5*2,0) | AO5: =IF(AND(O5>=7,O5<=8),15,IF(AND(O5>=6,O5<7),8,IF(O5>8,10,0)))+IF(P5>=80,10,IF(P5>=70,6,IF(P5>=60,3,0)))+IF(Q5<=60,15,IF(Q5<=70,10,IF(Q5<=80,5,0)))+IF(R5>=50,10,IF(R5>=40,6,IF(R5>=30,3,0)))+IF(S5>=45,15,IF(S5>=40,12,IF(S5>=35,8,IF(S5>=30,4,0))))+IF(T5>=10000,10,IF(T5>=8000,7,IF(T5>=6000,4,0)))+IF(U5<>"",U5*5,0)+IF(V5<>"",V5*10,0)+IF(W5<>"",W5*8,0)+IF(X5>=66,10,IF(X5>=50,6,IF(X5>=33,3,0))) | AP5: =IF(AA5=1,5,0)+IF(AB5=1,5,0)+IF(AC5=1,5,0)+IF(AD5=1,5,0)+IF(AE5=1,5,0)+IF(AF5=1,5,0) | AQ5: =IF(AG5<>"",AG5*8,0)+IF(AH5<>"",AH5*5,0)+IF(AI5<>"",AI5*10,0)+IF(AJ5<>"",AJ5*3,0)+IF(AK5=1,5,0)+IF(AL5<>"",AL5*5,0) | AR5: =AM5+AN5+AO5+AP5+AQ5
A6: 3 | B6: Sat | C6: 1.1 | D6: 1 | E6: 1 | F6: 0.1 | G6: 1 | AA6: 1 | AM6: =SUMPRODUCT((TRUNC(C6:G6))*10)+SUMPRODUCT(ROUND((C6:G6-TRUNC(C6:G6))*10,0)*5)+IF(H6="",0,H6*10) | AN6: =IF(AND(I6>=70,I6<=140),20,IF(AND(I6>140,I6<=180),10,0))+IF(J6>=70,15,IF(J6>=50,8,0))+IF(AND(K6>0,K6<=30),10,IF(AND(K6>30,K6<=50),5,0))+IF(L6=0,10,0)+IF(M6>0,5,0)+IF(N6<>"",N6*2,0) | AO6: =IF(AND(O6>=7,O6<=8),15,IF(AND(O6>=6,O6<7),8,IF(O6>8,10,0)))+IF(P6>=80,10,IF(P6>=70,6,IF(P6>=60,3,0)))+IF(Q6<=60,15,IF(Q6<=70,10,IF(Q6<=80,5,0)))+IF(R6>=50,10,IF(R6>=40,6,IF(R6>=30,3,0)))+IF(S6>=45,15,IF(S6>=40,12,IF(S6>=35,8,IF(S6>=30,4,0))))+IF(T6>=10000,10,IF(T6>=8000,7,IF(T6>=6000,4,0)))+IF(U6<>"",U6*5,0)+IF(V6<>"",V6*10,0)+IF(W6<>"",W6*8,0)+IF(X6>=66,10,IF(X6>=50,6,IF(X6>=33,3,0))) | AP6: =IF(AA6=1,5,0)+IF(AB6=1,5,0)+IF(AC6=1,5,0)+IF(AD6=1,5,0)+IF(AE6=1,5,0)+IF(AF6=1,5,0) | AQ6: =IF(AG6<>"",AG6*8,0)+IF(AH6<>"",AH6*5,0)+IF(AI6<>"",AI6*10,0)+IF(AJ6<>"",AJ6*3,0)+IF(AK6=1,5,0)+IF(AL6<>"",AL6*5,0) | AR6: =AM6+AN6+AO6+AP6+AQ6
A7: 4 | B7: Sun | C7: 1.2 | D7: 0.1 | E7: 1 | F7: 1 | G7: 1 | AA7: 1 | AB7: 1 | AM7: =SUMPRODUCT((TRUNC(C7:G7))*10)+SUMPRODUCT(ROUND((C7:G7-TRUNC(C7:G7))*10,0)*5)+IF(H7="",0,H7*10) | AN7: =IF(AND(I7>=70,I7<=140),20,IF(AND(I7>140,I7<=180),10,0))+IF(J7>=70,15,IF(J7>=50,8,0))+IF(AND(K7>0,K7<=30),10,IF(AND(K7>30,K7<=50),5,0))+IF(L7=0,10,0)+IF(M7>0,5,0)+IF(N7<>"",N7*2,0) | AO7: =IF(AND(O7>=7,O7<=8),15,IF(AND(O7>=6,O7<7),8,IF(O7>8,10,0)))+IF(P7>=80,10,IF(P7>=70,6,IF(P7>=60,3,0)))+IF(Q7<=60,15,IF(Q7<=70,10,IF(Q7<=80,5,0)))+IF(R7>=50,10,IF(R7>=40,6,IF(R7>=30,3,0)))+IF(S7>=45,15,IF(S7>=40,12,IF(S7>=35,8,IF(S7>=30,4,0))))+IF(T7>=10000,10,IF(T7>=8000,7,IF(T7>=6000,4,0)))+IF(U7<>"",U7*5,0)+IF(V7<>"",V7*10,0)+IF(W7<>"",W7*8,0)+IF(X7>=66,10,IF(X7>=50,6,IF(X7>=33,3,0))) | AP7: =IF(AA7=1,5,0)+IF(AB7=1,5,0)+IF(AC7=1,5,0)+IF(AD7=1,5,0)+IF(AE7=1,5,0)+IF(AF7=1,5,0) | AQ7: =IF(AG7<>"",AG7*8,0)+IF(AH7<>"",AH7*5,0)+IF(AI7<>"",AI7*10,0)+IF(AJ7<>"",AJ7*3,0)+IF(AK7=1,5,0)+IF(AL7<>"",AL7*5,0) | AR7: =AM7+AN7+AO7+AP7+AQ7
A8: 5 | B8: Mon | C8: 1 | D8: 0.1 | E8: 0.1 | F8: 0.1 | G8: 1 | AE8: 1 | AM8: =SUMPRODUCT((TRUNC(C8:G8))*10)+SUMPRODUCT(ROUND((C8:G8-TRUNC(C8:G8))*10,0)*5)+IF(H8="",0,H8*10) | AN8: =IF(AND(I8>=70,I8<=140),20,IF(AND(I8>140,I8<=180),10,0))+IF(J8>=70,15,IF(J8>=50,8,0))+IF(AND(K8>0,K8<=30),10,IF(AND(K8>30,K8<=50),5,0))+IF(L8=0,10,0)+IF(M8>0,5,0)+IF(N8<>"",N8*2,0) | AO8: =IF(AND(O8>=7,O8<=8),15,IF(AND(O8>=6,O8<7),8,IF(O8>8,10,0)))+IF(P8>=80,10,IF(P8>=70,6,IF(P8>=60,3,0)))+IF(Q8<=60,15,IF(Q8<=70,10,IF(Q8<=80,5,0)))+IF(R8>=50,10,IF(R8>=40,6,IF(R8>=30,3,0)))+IF(S8>=45,15,IF(S8>=40,12,IF(S8>=35,8,IF(S8>=30,4,0))))+IF(T8>=10000,10,IF(T8>=8000,7,IF(T8>=6000,4,0)))+IF(U8<>"",U8*5,0)+IF(V8<>"",V8*10,0)+IF(W8<>"",W8*8,0)+IF(X8>=66,10,IF(X8>=50,6,IF(X8>=33,3,0))) | AP8: =IF(AA8=1,5,0)+IF(AB8=1,5,0)+IF(AC8=1,5,0)+IF(AD8=1,5,0)+IF(AE8=1,5,0)+IF(AF8=1,5,0) | AQ8: =IF(AG8<>"",AG8*8,0)+IF(AH8<>"",AH8*5,0)+IF(AI8<>"",AI8*10,0)+IF(AJ8<>"",AJ8*3,0)+IF(AK8=1,5,0)+IF(AL8<>"",AL8*5,0) | AR8: =AM8+AN8+AO8+AP8+AQ8
A9: 6 | B9: Tue | C9: 1 | D9: 0.1 | E9: 0.1 | F9: 0.1 | G9: 0.1 | AA9: 1 | AB9: 1 | AC9: 1 | AD9: 1 | AE9: 1 | AF9: 1 | AM9: =SUMPRODUCT((TRUNC(C9:G9))*10)+SUMPRODUCT(ROUND((C9:G9-TRUNC(C9:G9))*10,0)*5)+IF(H9="",0,H9*10) | AN9: =IF(AND(I9>=70,I9<=140),20,IF(AND(I9>140,I9<=180),10,0))+IF(J9>=70,15,IF(J9>=50,8,0))+IF(AND(K9>0,K9<=30),10,IF(AND(K9>30,K9<=50),5,0))+IF(L9=0,10,0)+IF(M9>0,5,0)+IF(N9<>"",N9*2,0) | AO9: =IF(AND(O9>=7,O9<=8),15,IF(AND(O9>=6,O9<7),8,IF(O9>8,10,0)))+IF(P9>=80,10,IF(P9>=70,6,IF(P9>=60,3,0)))+IF(Q9<=60,15,IF(Q9<=70,10,IF(Q9<=80,5,0)))+IF(R9>=50,10,IF(R9>=40,6,IF(R9>=30,3,0)))+IF(S9>=45,15,IF(S9>=40,12,IF(S9>=35,8,IF(S9>=30,4,0))))+IF(T9>=10000,10,IF(T9>=8000,7,IF(T9>=6000,4,0)))+IF(U9<>"",U9*5,0)+IF(V9<>"",V9*10,0)+IF(W9<>"",W9*8,0)+IF(X9>=66,10,IF(X9>=50,6,IF(X9>=33,3,0))) | AP9: =IF(AA9=1,5,0)+IF(AB9=1,5,0)+IF(AC9=1,5,0)+IF(AD9=1,5,0)+IF(AE9=1,5,0)+IF(AF9=1,5,0) | AQ9: =IF(AG9<>"",AG9*8,0)+IF(AH9<>"",AH9*5,0)+IF(AI9<>"",AI9*10,0)+IF(AJ9<>"",AJ9*3,0)+IF(AK9=1,5,0)+IF(AL9<>"",AL9*5,0) | AR9: =AM9+AN9+AO9+AP9+AQ9
A10: 7 | B10: Wed | C10: 1 | D10: 0.1 | E10: 1 | F10: 1 | G10: 0.1 | AA10: 1 | AB10: 1 | AC10: 1 | AD10: 1 | AE10: 1 | AM10: =SUMPRODUCT((TRUNC(C10:G10))*10)+SUMPRODUCT(ROUND((C10:G10-TRUNC(C10:G10))*10,0)*5)+IF(H10="",0,H10*10) | AN10: =IF(AND(I10>=70,I10<=140),20,IF(AND(I10>140,I10<=180),10,0))+IF(J10>=70,15,IF(J10>=50,8,0))+IF(AND(K10>0,K10<=30),10,IF(AND(K10>30,K10<=50),5,0))+IF(L10=0,10,0)+IF(M10>0,5,0)+IF(N10<>"",N10*2,0) | AO10: =IF(AND(O10>=7,O10<=8),15,IF(AND(O10>=6,O10<7),8,IF(O10>8,10,0)))+IF(P10>=80,10,IF(P10>=70,6,IF(P10>=60,3,0)))+IF(Q10<=60,15,IF(Q10<=70,10,IF(Q10<=80,5,0)))+IF(R10>=50,10,IF(R10>=40,6,IF(R10>=30,3,0)))+IF(S10>=45,15,IF(S10>=40,12,IF(S10>=35,8,IF(S10>=30,4,0))))+IF(T10>=10000,10,IF(T10>=8000,7,IF(T10>=6000,4,0)))+IF(U10<>"",U10*5,0)+IF(V10<>"",V10*10,0)+IF(W10<>"",W10*8,0)+IF(X10>=66,10,IF(X10>=50,6,IF(X10>=33,3,0))) | AP10: =IF(AA10=1,5,0)+IF(AB10=1,5,0)+IF(AC10=1,5,0)+IF(AD10=1,5,0)+IF(AE10=1,5,0)+IF(AF10=1,5,0) | AQ10: =IF(AG10<>"",AG10*8,0)+IF(AH10<>"",AH10*5,0)+IF(AI10<>"",AI10*10,0)+IF(AJ10<>"",AJ10*3,0)+IF(AK10=1,5,0)+IF(AL10<>"",AL10*5,0) | AR10: =AM10+AN10+AO10+AP10+AQ10
A11: 8 | B11: Thu | C11: 0.1 | D11: 1 | E11: 1 | F11: 0.1 | G11: 0.1 | AA11: 1 | AE11: 1 | AM11: =SUMPRODUCT((TRUNC(C11:G11))*10)+SUMPRODUCT(ROUND((C11:G11-TRUNC(C11:G11))*10,0)*5)+IF(H11="",0,H11*10) | AN11: =IF(AND(I11>=70,I11<=140),20,IF(AND(I11>140,I11<=180),10,0))+IF(J11>=70,15,IF(J11>=50,8,0))+IF(AND(K11>0,K11<=30),10,IF(AND(K11>30,K11<=50),5,0))+IF(L11=0,10,0)+IF(M11>0,5,0)+IF(N11<>"",N11*2,0) | AO11: =IF(AND(O11>=7,O11<=8),15,IF(AND(O11>=6,O11<7),8,IF(O11>8,10,0)))+IF(P11>=80,10,IF(P11>=70,6,IF(P11>=60,3,0)))+IF(Q11<=60,15,IF(Q11<=70,10,IF(Q11<=80,5,0)))+IF(R11>=50,10,IF(R11>=40,6,IF(R11>=30,3,0)))+IF(S11>=45,15,IF(S11>=40,12,IF(S11>=35,8,IF(S11>=30,4,0))))+IF(T11>=10000,10,IF(T11>=8000,7,IF(T11>=6000,4,0)))+IF(U11<>"",U11*5,0)+IF(V11<>"",V11*10,0)+IF(W11<>"",W11*8,0)+IF(X11>=66,10,IF(X11>=50,6,IF(X11>=33,3,0))) | AP11: =IF(AA11=1,5,0)+IF(AB11=1,5,0)+IF(AC11=1,5,0)+IF(AD11=1,5,0)+IF(AE11=1,5,0)+IF(AF11=1,5,0) | AQ11: =IF(AG11<>"",AG11*8,0)+IF(AH11<>"",AH11*5,0)+IF(AI11<>"",AI11*10,0)+IF(AJ11<>"",AJ11*3,0)+IF(AK11=1,5,0)+IF(AL11<>"",AL11*5,0) | AR11: =AM11+AN11+AO11+AP11+AQ11
A12: 9 | B12: Fri | C12: 1 | D12: 1 | E12: 1 | F12: 1 | G12: 1 | AA12: 1 | AE12: 1 | AM12: =SUMPRODUCT((TRUNC(C12:G12))*10)+SUMPRODUCT(ROUND((C12:G12-TRUNC(C12:G12))*10,0)*5)+IF(H12="",0,H12*10) | AN12: =IF(AND(I12>=70,I12<=140),20,IF(AND(I12>140,I12<=180),10,0))+IF(J12>=70,15,IF(J12>=50,8,0))+IF(AND(K12>0,K12<=30),10,IF(AND(K12>30,K12<=50),5,0))+IF(L12=0,10,0)+IF(M12>0,5,0)+IF(N12<>"",N12*2,0) | AO12: =IF(AND(O12>=7,O12<=8),15,IF(AND(O12>=6,O12<7),8,IF(O12>8,10,0)))+IF(P12>=80,10,IF(P12>=70,6,IF(P12>=60,3,0)))+IF(Q12<=60,15,IF(Q12<=70,10,IF(Q12<=80,5,0)))+IF(R12>=50,10,IF(R12>=40,6,IF(R12>=30,3,0)))+IF(S12>=45,15,IF(S12>=40,12,IF(S12>=35,8,IF(S12>=30,4,0))))+IF(T12>=10000,10,IF(T12>=8000,7,IF(T12>=6000,4,0)))+IF(U12<>"",U12*5,0)+IF(V12<>"",V12*10,0)+IF(W12<>"",W12*8,0)+IF(X12>=66,10,IF(X12>=50,6,IF(X12>=33,3,0))) | AP12: =IF(AA12=1,5,0)+IF(AB12=1,5,0)+IF(AC12=1,5,0)+IF(AD12=1,5,0)+IF(AE12=1,5,0)+IF(AF12=1,5,0) | AQ12: =IF(AG12<>"",AG12*8,0)+IF(AH12<>"",AH12*5,0)+IF(AI12<>"",AI12*10,0)+IF(AJ12<>"",AJ12*3,0)+IF(AK12=1,5,0)+IF(AL12<>"",AL12*5,0) | AR12: =AM12+AN12+AO12+AP12+AQ12
A13: 10 | B13: Sat | C13: 0.1 | D13: 1 | E13: 1 | F13: 1 | G13: 1 | AA13: 1 | AE13: 1 | AF13: 1 | AM13: =SUMPRODUCT((TRUNC(C13:G13))*10)+SUMPRODUCT(ROUND((C13:G13-TRUNC(C13:G13))*10,0)*5)+IF(H13="",0,H13*10) | AN13: =IF(AND(I13>=70,I13<=140),20,IF(AND(I13>140,I13<=180),10,0))+IF(J13>=70,15,IF(J13>=50,8,0))+IF(AND(K13>0,K13<=30),10,IF(AND(K13>30,K13<=50),5,0))+IF(L13=0,10,0)+IF(M13>0,5,0)+IF(N13<>"",N13*2,0) | AO13: =IF(AND(O13>=7,O13<=8),15,IF(AND(O13>=6,O13<7),8,IF(O13>8,10,0)))+IF(P13>=80,10,IF(P13>=70,6,IF(P13>=60,3,0)))+IF(Q13<=60,15,IF(Q13<=70,10,IF(Q13<=80,5,0)))+IF(R13>=50,10,IF(R13>=40,6,IF(R13>=30,3,0)))+IF(S13>=45,15,IF(S13>=40,12,IF(S13>=35,8,IF(S13>=30,4,0))))+IF(T13>=10000,10,IF(T13>=8000,7,IF(T13>=6000,4,0)))+IF(U13<>"",U13*5,0)+IF(V13<>"",V13*10,0)+IF(W13<>"",W13*8,0)+IF(X13>=66,10,IF(X13>=50,6,IF(X13>=33,3,0))) | AP13: =IF(AA13=1,5,0)+IF(AB13=1,5,0)+IF(AC13=1,5,0)+IF(AD13=1,5,0)+IF(AE13=1,5,0)+IF(AF13=1,5,0) | AQ13: =IF(AG13<>"",AG13*8,0)+IF(AH13<>"",AH13*5,0)+IF(AI13<>"",AI13*10,0)+IF(AJ13<>"",AJ13*3,0)+IF(AK13=1,5,0)+IF(AL13<>"",AL13*5,0) | AR13: =AM13+AN13+AO13+AP13+AQ13
A14: 11 | B14: Sun | C14: 1 | D14: 0.1 | E14: 0.1 | F14: 1 | G14: 0.1 | AA14: 1 | AB14: 1 | AE14: 1 | AF14: 1 | AM14: =SUMPRODUCT((TRUNC(C14:G14))*10)+SUMPRODUCT(ROUND((C14:G14-TRUNC(C14:G14))*10,0)*5)+IF(H14="",0,H14*10) | AN14: =IF(AND(I14>=70,I14<=140),20,IF(AND(I14>140,I14<=180),10,0))+IF(J14>=70,15,IF(J14>=50,8,0))+IF(AND(K14>0,K14<=30),10,IF(AND(K14>30,K14<=50),5,0))+IF(L14=0,10,0)+IF(M14>0,5,0)+IF(N14<>"",N14*2,0) | AO14: =IF(AND(O14>=7,O14<=8),15,IF(AND(O14>=6,O14<7),8,IF(O14>8,10,0)))+IF(P14>=80,10,IF(P14>=70,6,IF(P14>=60,3,0)))+IF(Q14<=60,15,IF(Q14<=70,10,IF(Q14<=80,5,0)))+IF(R14>=50,10,IF(R14>=40,6,IF(R14>=30,3,0)))+IF(S14>=45,15,IF(S14>=40,12,IF(S14>=35,8,IF(S14>=30,4,0))))+IF(T14>=10000,10,IF(T14>=8000,7,IF(T14>=6000,4,0)))+IF(U14<>"",U14*5,0)+IF(V14<>"",V14*10,0)+IF(W14<>"",W14*8,0)+IF(X14>=66,10,IF(X14>=50,6,IF(X14>=33,3,0))) | AP14: =IF(AA14=1,5,0)+IF(AB14=1,5,0)+IF(AC14=1,5,0)+IF(AD14=1,5,0)+IF(AE14=1,5,0)+IF(AF14=1,5,0) | AQ14: =IF(AG14<>"",AG14*8,0)+IF(AH14<>"",AH14*5,0)+IF(AI14<>"",AI14*10,0)+IF(AJ14<>"",AJ14*3,0)+IF(AK14=1,5,0)+IF(AL14<>"",AL14*5,0) | AR14: =AM14+AN14+AO14+AP14+AQ14
A15: 12 | B15: Mon | C15: 0.1 | E15: 0.1 | F15: 0.1 | G15: 1 | AB15: 1 | AE15: 1 | AF15: 1 | AM15: =SUMPRODUCT((TRUNC(C15:G15))*10)+SUMPRODUCT(ROUND((C15:G15-TRUNC(C15:G15))*10,0)*5)+IF(H15="",0,H15*10) | AN15: =IF(AND(I15>=70,I15<=140),20,IF(AND(I15>140,I15<=180),10,0))+IF(J15>=70,15,IF(J15>=50,8,0))+IF(AND(K15>0,K15<=30),10,IF(AND(K15>30,K15<=50),5,0))+IF(L15=0,10,0)+IF(M15>0,5,0)+IF(N15<>"",N15*2,0) | AO15: =IF(AND(O15>=7,O15<=8),15,IF(AND(O15>=6,O15<7),8,IF(O15>8,10,0)))+IF(P15>=80,10,IF(P15>=70,6,IF(P15>=60,3,0)))+IF(Q15<=60,15,IF(Q15<=70,10,IF(Q15<=80,5,0)))+IF(R15>=50,10,IF(R15>=40,6,IF(R15>=30,3,0)))+IF(S15>=45,15,IF(S15>=40,12,IF(S15>=35,8,IF(S15>=30,4,0))))+IF(T15>=10000,10,IF(T15>=8000,7,IF(T15>=6000,4,0)))+IF(U15<>"",U15*5,0)+IF(V15<>"",V15*10,0)+IF(W15<>"",W15*8,0)+IF(X15>=66,10,IF(X15>=50,6,IF(X15>=33,3,0))) | AP15: =IF(AA15=1,5,0)+IF(AB15=1,5,0)+IF(AC15=1,5,0)+IF(AD15=1,5,0)+IF(AE15=1,5,0)+IF(AF15=1,5,0) | AQ15: =IF(AG15<>"",AG15*8,0)+IF(AH15<>"",AH15*5,0)+IF(AI15<>"",AI15*10,0)+IF(AJ15<>"",AJ15*3,0)+IF(AK15=1,5,0)+IF(AL15<>"",AL15*5,0) | AR15: =AM15+AN15+AO15+AP15+AQ15
A16: 13 | B16: Tue | C16: 0.1 | F16: 0.1 | G16: 0.1 | AA16: 1 | AB16: 1 | AC16: 1 | AE16: 1 | AF16: 1 | AM16: =SUMPRODUCT((TRUNC(C16:G16))*10)+SUMPRODUCT(ROUND((C16:G16-TRUNC(C16:G16))*10,0)*5)+IF(H16="",0,H16*10) | AN16: =IF(AND(I16>=70,I16<=140),20,IF(AND(I16>140,I16<=180),10,0))+IF(J16>=70,15,IF(J16>=50,8,0))+IF(AND(K16>0,K16<=30),10,IF(AND(K16>30,K16<=50),5,0))+IF(L16=0,10,0)+IF(M16>0,5,0)+IF(N16<>"",N16*2,0) | AO16: =IF(AND(O16>=7,O16<=8),15,IF(AND(O16>=6,O16<7),8,IF(O16>8,10,0)))+IF(P16>=80,10,IF(P16>=70,6,IF(P16>=60,3,0)))+IF(Q16<=60,15,IF(Q16<=70,10,IF(Q16<=80,5,0)))+IF(R16>=50,10,IF(R16>=40,6,IF(R16>=30,3,0)))+IF(S16>=45,15,IF(S16>=40,12,IF(S16>=35,8,IF(S16>=30,4,0))))+IF(T16>=10000,10,IF(T16>=8000,7,IF(T16>=6000,4,0)))+IF(U16<>"",U16*5,0)+IF(V16<>"",V16*10,0)+IF(W16<>"",W16*8,0)+IF(X16>=66,10,IF(X16>=50,6,IF(X16>=33,3,0))) | AP16: =IF(AA16=1,5,0)+IF(AB16=1,5,0)+IF(AC16=1,5,0)+IF(AD16=1,5,0)+IF(AE16=1,5,0)+IF(AF16=1,5,0) | AQ16: =IF(AG16<>"",AG16*8,0)+IF(AH16<>"",AH16*5,0)+IF(AI16<>"",AI16*10,0)+IF(AJ16<>"",AJ16*3,0)+IF(AK16=1,5,0)+IF(AL16<>"",AL16*5,0) | AR16: =AM16+AN16+AO16+AP16+AQ16
A17: 14 | B17: Wed | C17: 1 | D17: 0.1 | E17: 0.1 | F17: 0.1 | G17: 0.1 | AA17: 1 | AB17: 1 | AD17: 1 | AE17: 1 | AF17: 1 | AM17: =SUMPRODUCT((TRUNC(C17:G17))*10)+SUMPRODUCT(ROUND((C17:G17-TRUNC(C17:G17))*10,0)*5)+IF(H17="",0,H17*10) | AN17: =IF(AND(I17>=70,I17<=140),20,IF(AND(I17>140,I17<=180),10,0))+IF(J17>=70,15,IF(J17>=50,8,0))+IF(AND(K17>0,K17<=30),10,IF(AND(K17>30,K17<=50),5,0))+IF(L17=0,10,0)+IF(M17>0,5,0)+IF(N17<>"",N17*2,0) | AO17: =IF(AND(O17>=7,O17<=8),15,IF(AND(O17>=6,O17<7),8,IF(O17>8,10,0)))+IF(P17>=80,10,IF(P17>=70,6,IF(P17>=60,3,0)))+IF(Q17<=60,15,IF(Q17<=70,10,IF(Q17<=80,5,0)))+IF(R17>=50,10,IF(R17>=40,6,IF(R17>=30,3,0)))+IF(S17>=45,15,IF(S17>=40,12,IF(S17>=35,8,IF(S17>=30,4,0))))+IF(T17>=10000,10,IF(T17>=8000,7,IF(T17>=6000,4,0)))+IF(U17<>"",U17*5,0)+IF(V17<>"",V17*10,0)+IF(W17<>"",W17*8,0)+IF(X17>=66,10,IF(X17>=50,6,IF(X17>=33,3,0))) | AP17: =IF(AA17=1,5,0)+IF(AB17=1,5,0)+IF(AC17=1,5,0)+IF(AD17=1,5,0)+IF(AE17=1,5,0)+IF(AF17=1,5,0) | AQ17: =IF(AG17<>"",AG17*8,0)+IF(AH17<>"",AH17*5,0)+IF(AI17<>"",AI17*10,0)+IF(AJ17<>"",AJ17*3,0)+IF(AK17=1,5,0)+IF(AL17<>"",AL17*5,0) | AR17: =AM17+AN17+AO17+AP17+AQ17
A18: 15 | B18: Thu | C18: 1 | F18: 0.1 | G18: 0.1 | AA18: 1 | AB18: 1 | AE18: 1 | AF18: 1 | AM18: =SUMPRODUCT((TRUNC(C18:G18))*10)+SUMPRODUCT(ROUND((C18:G18-TRUNC(C18:G18))*10,0)*5)+IF(H18="",0,H18*10) | AN18: =IF(AND(I18>=70,I18<=140),20,IF(AND(I18>140,I18<=180),10,0))+IF(J18>=70,15,IF(J18>=50,8,0))+IF(AND(K18>0,K18<=30),10,IF(AND(K18>30,K18<=50),5,0))+IF(L18=0,10,0)+IF(M18>0,5,0)+IF(N18<>"",N18*2,0) | AO18: =IF(AND(O18>=7,O18<=8),15,IF(AND(O18>=6,O18<7),8,IF(O18>8,10,0)))+IF(P18>=80,10,IF(P18>=70,6,IF(P18>=60,3,0)))+IF(Q18<=60,15,IF(Q18<=70,10,IF(Q18<=80,5,0)))+IF(R18>=50,10,IF(R18>=40,6,IF(R18>=30,3,0)))+IF(S18>=45,15,IF(S18>=40,12,IF(S18>=35,8,IF(S18>=30,4,0))))+IF(T18>=10000,10,IF(T18>=8000,7,IF(T18>=6000,4,0)))+IF(U18<>"",U18*5,0)+IF(V18<>"",V18*10,0)+IF(W18<>"",W18*8,0)+IF(X18>=66,10,IF(X18>=50,6,IF(X18>=33,3,0))) | AP18: =IF(AA18=1,5,0)+IF(AB18=1,5,0)+IF(AC18=1,5,0)+IF(AD18=1,5,0)+IF(AE18=1,5,0)+IF(AF18=1,5,0) | AQ18: =IF(AG18<>"",AG18*8,0)+IF(AH18<>"",AH18*5,0)+IF(AI18<>"",AI18*10,0)+IF(AJ18<>"",AJ18*3,0)+IF(AK18=1,5,0)+IF(AL18<>"",AL18*5,0) | AR18: =AM18+AN18+AO18+AP18+AQ18
A19: 16 | B19: Fri | C19: 1 | G19: 0.1 | AA19: 1 | AB19: 1 | AD19: 1 | AE19: 1 | AF19: 1 | AM19: =SUMPRODUCT((TRUNC(C19:G19))*10)+SUMPRODUCT(ROUND((C19:G19-TRUNC(C19:G19))*10,0)*5)+IF(H19="",0,H19*10) | AN19: =IF(AND(I19>=70,I19<=140),20,IF(AND(I19>140,I19<=180),10,0))+IF(J19>=70,15,IF(J19>=50,8,0))+IF(AND(K19>0,K19<=30),10,IF(AND(K19>30,K19<=50),5,0))+IF(L19=0,10,0)+IF(M19>0,5,0)+IF(N19<>"",N19*2,0) | AO19: =IF(AND(O19>=7,O19<=8),15,IF(AND(O19>=6,O19<7),8,IF(O19>8,10,0)))+IF(P19>=80,10,IF(P19>=70,6,IF(P19>=60,3,0)))+IF(Q19<=60,15,IF(Q19<=70,10,IF(Q19<=80,5,0)))+IF(R19>=50,10,IF(R19>=40,6,IF(R19>=30,3,0)))+IF(S19>=45,15,IF(S19>=40,12,IF(S19>=35,8,IF(S19>=30,4,0))))+IF(T19>=10000,10,IF(T19>=8000,7,IF(T19>=6000,4,0)))+IF(U19<>"",U19*5,0)+IF(V19<>"",V19*10,0)+IF(W19<>"",W19*8,0)+IF(X19>=66,10,IF(X19>=50,6,IF(X19>=33,3,0))) | AP19: =IF(AA19=1,5,0)+IF(AB19=1,5,0)+IF(AC19=1,5,0)+IF(AD19=1,5,0)+IF(AE19=1,5,0)+IF(AF19=1,5,0) | AQ19: =IF(AG19<>"",AG19*8,0)+IF(AH19<>"",AH19*5,0)+IF(AI19<>"",AI19*10,0)+IF(AJ19<>"",AJ19*3,0)+IF(AK19=1,5,0)+IF(AL19<>"",AL19*5,0) | AR19: =AM19+AN19+AO19+AP19+AQ19
A20: 17 | B20: Sat | C20: 1 | D20: 1 | E20: 1 | F20: 0.1 | G20: 0.1 | AA20: 1 | AB20: 1 | AD20: 1 | AE20: 1 | AF20: 1 | AM20: =SUMPRODUCT((TRUNC(C20:G20))*10)+SUMPRODUCT(ROUND((C20:G20-TRUNC(C20:G20))*10,0)*5)+IF(H20="",0,H20*10) | AN20: =IF(AND(I20>=70,I20<=140),20,IF(AND(I20>140,I20<=180),10,0))+IF(J20>=70,15,IF(J20>=50,8,0))+IF(AND(K20>0,K20<=30),10,IF(AND(K20>30,K20<=50),5,0))+IF(L20=0,10,0)+IF(M20>0,5,0)+IF(N20<>"",N20*2,0) | AO20: =IF(AND(O20>=7,O20<=8),15,IF(AND(O20>=6,O20<7),8,IF(O20>8,10,0)))+IF(P20>=80,10,IF(P20>=70,6,IF(P20>=60,3,0)))+IF(Q20<=60,15,IF(Q20<=70,10,IF(Q20<=80,5,0)))+IF(R20>=50,10,IF(R20>=40,6,IF(R20>=30,3,0)))+IF(S20>=45,15,IF(S20>=40,12,IF(S20>=35,8,IF(S20>=30,4,0))))+IF(T20>=10000,10,IF(T20>=8000,7,IF(T20>=6000,4,0)))+IF(U20<>"",U20*5,0)+IF(V20<>"",V20*10,0)+IF(W20<>"",W20*8,0)+IF(X20>=66,10,IF(X20>=50,6,IF(X20>=33,3,0))) | AP20: =IF(AA20=1,5,0)+IF(AB20=1,5,0)+IF(AC20=1,5,0)+IF(AD20=1,5,0)+IF(AE20=1,5,0)+IF(AF20=1,5,0) | AQ20: =IF(AG20<>"",AG20*8,0)+IF(AH20<>"",AH20*5,0)+IF(AI20<>"",AI20*10,0)+IF(AJ20<>"",AJ20*3,0)+IF(AK20=1,5,0)+IF(AL20<>"",AL20*5,0) | AR20: =AM20+AN20+AO20+AP20+AQ20
A21: 18 | B21: Sun | C21: 1 | D21: 1 | E21: 0.1 | F21: 1 | G21: 0.1 | AA21: 1 | AB21: 1 | AE21: 1 | AF21: 1 | AM21: =SUMPRODUCT((TRUNC(C21:G21))*10)+SUMPRODUCT(ROUND((C21:G21-TRUNC(C21:G21))*10,0)*5)+IF(H21="",0,H21*10) | AN21: =IF(AND(I21>=70,I21<=140),20,IF(AND(I21>140,I21<=180),10,0))+IF(J21>=70,15,IF(J21>=50,8,0))+IF(AND(K21>0,K21<=30),10,IF(AND(K21>30,K21<=50),5,0))+IF(L21=0,10,0)+IF(M21>0,5,0)+IF(N21<>"",N21*2,0) | AO21: =IF(AND(O21>=7,O21<=8),15,IF(AND(O21>=6,O21<7),8,IF(O21>8,10,0)))+IF(P21>=80,10,IF(P21>=70,6,IF(P21>=60,3,0)))+IF(Q21<=60,15,IF(Q21<=70,10,IF(Q21<=80,5,0)))+IF(R21>=50,10,IF(R21>=40,6,IF(R21>=30,3,0)))+IF(S21>=45,15,IF(S21>=40,12,IF(S21>=35,8,IF(S21>=30,4,0))))+IF(T21>=10000,10,IF(T21>=8000,7,IF(T21>=6000,4,0)))+IF(U21<>"",U21*5,0)+IF(V21<>"",V21*10,0)+IF(W21<>"",W21*8,0)+IF(X21>=66,10,IF(X21>=50,6,IF(X21>=33,3,0))) | AP21: =IF(AA21=1,5,0)+IF(AB21=1,5,0)+IF(AC21=1,5,0)+IF(AD21=1,5,0)+IF(AE21=1,5,0)+IF(AF21=1,5,0) | AQ21: =IF(AG21<>"",AG21*8,0)+IF(AH21<>"",AH21*5,0)+IF(AI21<>"",AI21*10,0)+IF(AJ21<>"",AJ21*3,0)+IF(AK21=1,5,0)+IF(AL21<>"",AL21*5,0) | AR21: =AM21+AN21+AO21+AP21+AQ21
A22: 19 | B22: Mon | C22: 1 | F22: 1 | G22: 0.1 | AA22: 1 | AE22: 1 | AF22: 1 | AM22: =SUMPRODUCT((TRUNC(C22:G22))*10)+SUMPRODUCT(ROUND((C22:G22-TRUNC(C22:G22))*10,0)*5)+IF(H22="",0,H22*10) | AN22: =IF(AND(I22>=70,I22<=140),20,IF(AND(I22>140,I22<=180),10,0))+IF(J22>=70,15,IF(J22>=50,8,0))+IF(AND(K22>0,K22<=30),10,IF(AND(K22>30,K22<=50),5,0))+IF(L22=0,10,0)+IF(M22>0,5,0)+IF(N22<>"",N22*2,0) | AO22: =IF(AND(O22>=7,O22<=8),15,IF(AND(O22>=6,O22<7),8,IF(O22>8,10,0)))+IF(P22>=80,10,IF(P22>=70,6,IF(P22>=60,3,0)))+IF(Q22<=60,15,IF(Q22<=70,10,IF(Q22<=80,5,0)))+IF(R22>=50,10,IF(R22>=40,6,IF(R22>=30,3,0)))+IF(S22>=45,15,IF(S22>=40,12,IF(S22>=35,8,IF(S22>=30,4,0))))+IF(T22>=10000,10,IF(T22>=8000,7,IF(T22>=6000,4,0)))+IF(U22<>"",U22*5,0)+IF(V22<>"",V22*10,0)+IF(W22<>"",W22*8,0)+IF(X22>=66,10,IF(X22>=50,6,IF(X22>=33,3,0))) | AP22: =IF(AA22=1,5,0)+IF(AB22=1,5,0)+IF(AC22=1,5,0)+IF(AD22=1,5,0)+IF(AE22=1,5,0)+IF(AF22=1,5,0) | AQ22: =IF(AG22<>"",AG22*8,0)+IF(AH22<>"",AH22*5,0)+IF(AI22<>"",AI22*10,0)+IF(AJ22<>"",AJ22*3,0)+IF(AK22=1,5,0)+IF(AL22<>"",AL22*5,0) | AR22: =AM22+AN22+AO22+AP22+AQ22
A23: 20 | B23: Tue | C23: 1 | G23: 0.1 | AA23: 1 | AB23: 1 | AD23: 1 | AE23: 1 | AF23: 1 | AM23: =SUMPRODUCT((TRUNC(C23:G23))*10)+SUMPRODUCT(ROUND((C23:G23-TRUNC(C23:G23))*10,0)*5)+IF(H23="",0,H23*10) | AN23: =IF(AND(I23>=70,I23<=140),20,IF(AND(I23>140,I23<=180),10,0))+IF(J23>=70,15,IF(J23>=50,8,0))+IF(AND(K23>0,K23<=30),10,IF(AND(K23>30,K23<=50),5,0))+IF(L23=0,10,0)+IF(M23>0,5,0)+IF(N23<>"",N23*2,0) | AO23: =IF(AND(O23>=7,O23<=8),15,IF(AND(O23>=6,O23<7),8,IF(O23>8,10,0)))+IF(P23>=80,10,IF(P23>=70,6,IF(P23>=60,3,0)))+IF(Q23<=60,15,IF(Q23<=70,10,IF(Q23<=80,5,0)))+IF(R23>=50,10,IF(R23>=40,6,IF(R23>=30,3,0)))+IF(S23>=45,15,IF(S23>=40,12,IF(S23>=35,8,IF(S23>=30,4,0))))+IF(T23>=10000,10,IF(T23>=8000,7,IF(T23>=6000,4,0)))+IF(U23<>"",U23*5,0)+IF(V23<>"",V23*10,0)+IF(W23<>"",W23*8,0)+IF(X23>=66,10,IF(X23>=50,6,IF(X23>=33,3,0))) | AP23: =IF(AA23=1,5,0)+IF(AB23=1,5,0)+IF(AC23=1,5,0)+IF(AD23=1,5,0)+IF(AE23=1,5,0)+IF(AF23=1,5,0) | AQ23: =IF(AG23<>"",AG23*8,0)+IF(AH23<>"",AH23*5,0)+IF(AI23<>"",AI23*10,0)+IF(AJ23<>"",AJ23*3,0)+IF(AK23=1,5,0)+IF(AL23<>"",AL23*5,0) | AR23: =AM23+AN23+AO23+AP23+AQ23
A24: 21 | B24: Wed | C24: 0.1 | G24: 0.1 | AA24: 1 | AB24: 1 | AD24: 1 | AE24: 1 | AF24: 1 | AM24: =SUMPRODUCT((TRUNC(C24:G24))*10)+SUMPRODUCT(ROUND((C24:G24-TRUNC(C24:G24))*10,0)*5)+IF(H24="",0,H24*10) | AN24: =IF(AND(I24>=70,I24<=140),20,IF(AND(I24>140,I24<=180),10,0))+IF(J24>=70,15,IF(J24>=50,8,0))+IF(AND(K24>0,K24<=30),10,IF(AND(K24>30,K24<=50),5,0))+IF(L24=0,10,0)+IF(M24>0,5,0)+IF(N24<>"",N24*2,0) | AO24: =IF(AND(O24>=7,O24<=8),15,IF(AND(O24>=6,O24<7),8,IF(O24>8,10,0)))+IF(P24>=80,10,IF(P24>=70,6,IF(P24>=60,3,0)))+IF(Q24<=60,15,IF(Q24<=70,10,IF(Q24<=80,5,0)))+IF(R24>=50,10,IF(R24>=40,6,IF(R24>=30,3,0)))+IF(S24>=45,15,IF(S24>=40,12,IF(S24>=35,8,IF(S24>=30,4,0))))+IF(T24>=10000,10,IF(T24>=8000,7,IF(T24>=6000,4,0)))+IF(U24<>"",U24*5,0)+IF(V24<>"",V24*10,0)+IF(W24<>"",W24*8,0)+IF(X24>=66,10,IF(X24>=50,6,IF(X24>=33,3,0))) | AP24: =IF(AA24=1,5,0)+IF(AB24=1,5,0)+IF(AC24=1,5,0)+IF(AD24=1,5,0)+IF(AE24=1,5,0)+IF(AF24=1,5,0) | AQ24: =IF(AG24<>"",AG24*8,0)+IF(AH24<>"",AH24*5,0)+IF(AI24<>"",AI24*10,0)+IF(AJ24<>"",AJ24*3,0)+IF(AK24=1,5,0)+IF(AL24<>"",AL24*5,0) | AR24: =AM24+AN24+AO24+AP24+AQ24
A25: 22 | B25: Thu | C25: 1 | G25: 0.1 | AA25: 1 | AB25: 1 | AC25: 1 | AD25: 1 | AE25: 1 | AF25: 1 | AM25: =SUMPRODUCT((TRUNC(C25:G25))*10)+SUMPRODUCT(ROUND((C25:G25-TRUNC(C25:G25))*10,0)*5)+IF(H25="",0,H25*10) | AN25: =IF(AND(I25>=70,I25<=140),20,IF(AND(I25>140,I25<=180),10,0))+IF(J25>=70,15,IF(J25>=50,8,0))+IF(AND(K25>0,K25<=30),10,IF(AND(K25>30,K25<=50),5,0))+IF(L25=0,10,0)+IF(M25>0,5,0)+IF(N25<>"",N25*2,0) | AO25: =IF(AND(O25>=7,O25<=8),15,IF(AND(O25>=6,O25<7),8,IF(O25>8,10,0)))+IF(P25>=80,10,IF(P25>=70,6,IF(P25>=60,3,0)))+IF(Q25<=60,15,IF(Q25<=70,10,IF(Q25<=80,5,0)))+IF(R25>=50,10,IF(R25>=40,6,IF(R25>=30,3,0)))+IF(S25>=45,15,IF(S25>=40,12,IF(S25>=35,8,IF(S25>=30,4,0))))+IF(T25>=10000,10,IF(T25>=8000,7,IF(T25>=6000,4,0)))+IF(U25<>"",U25*5,0)+IF(V25<>"",V25*10,0)+IF(W25<>"",W25*8,0)+IF(X25>=66,10,IF(X25>=50,6,IF(X25>=33,3,0))) | AP25: =IF(AA25=1,5,0)+IF(AB25=1,5,0)+IF(AC25=1,5,0)+IF(AD25=1,5,0)+IF(AE25=1,5,0)+IF(AF25=1,5,0) | AQ25: =IF(AG25<>"",AG25*8,0)+IF(AH25<>"",AH25*5,0)+IF(AI25<>"",AI25*10,0)+IF(AJ25<>"",AJ25*3,0)+IF(AK25=1,5,0)+IF(AL25<>"",AL25*5,0) | AR25: =AM25+AN25+AO25+AP25+AQ25
A26: 23 | B26: Fri | AM26: =SUMPRODUCT((TRUNC(C26:G26))*10)+SUMPRODUCT(ROUND((C26:G26-TRUNC(C26:G26))*10,0)*5)+IF(H26="",0,H26*10) | AN26: =IF(AND(I26>=70,I26<=140),20,IF(AND(I26>140,I26<=180),10,0))+IF(J26>=70,15,IF(J26>=50,8,0))+IF(AND(K26>0,K26<=30),10,IF(AND(K26>30,K26<=50),5,0))+IF(L26=0,10,0)+IF(M26>0,5,0)+IF(N26<>"",N26*2,0) | AO26: =IF(AND(O26>=7,O26<=8),15,IF(AND(O26>=6,O26<7),8,IF(O26>8,10,0)))+IF(P26>=80,10,IF(P26>=70,6,IF(P26>=60,3,0)))+IF(Q26<=60,15,IF(Q26<=70,10,IF(Q26<=80,5,0)))+IF(R26>=50,10,IF(R26>=40,6,IF(R26>=30,3,0)))+IF(S26>=45,15,IF(S26>=40,12,IF(S26>=35,8,IF(S26>=30,4,0))))+IF(T26>=10000,10,IF(T26>=8000,7,IF(T26>=6000,4,0)))+IF(U26<>"",U26*5,0)+IF(V26<>"",V26*10,0)+IF(W26<>"",W26*8,0)+IF(X26>=66,10,IF(X26>=50,6,IF(X26>=33,3,0))) | AP26: =IF(AA26=1,5,0)+IF(AB26=1,5,0)+IF(AC26=1,5,0)+IF(AD26=1,5,0)+IF(AE26=1,5,0)+IF(AF26=1,5,0) | AQ26: =IF(AG26<>"",AG26*8,0)+IF(AH26<>"",AH26*5,0)+IF(AI26<>"",AI26*10,0)+IF(AJ26<>"",AJ26*3,0)+IF(AK26=1,5,0)+IF(AL26<>"",AL26*5,0) | AR26: =AM26+AN26+AO26+AP26+AQ26
A27: 24 | B27: Sat | AM27: =SUMPRODUCT((TRUNC(C27:G27))*10)+SUMPRODUCT(ROUND((C27:G27-TRUNC(C27:G27))*10,0)*5)+IF(H27="",0,H27*10) | AN27: =IF(AND(I27>=70,I27<=140),20,IF(AND(I27>140,I27<=180),10,0))+IF(J27>=70,15,IF(J27>=50,8,0))+IF(AND(K27>0,K27<=30),10,IF(AND(K27>30,K27<=50),5,0))+IF(L27=0,10,0)+IF(M27>0,5,0)+IF(N27<>"",N27*2,0) | AO27: =IF(AND(O27>=7,O27<=8),15,IF(AND(O27>=6,O27<7),8,IF(O27>8,10,0)))+IF(P27>=80,10,IF(P27>=70,6,IF(P27>=60,3,0)))+IF(Q27<=60,15,IF(Q27<=70,10,IF(Q27<=80,5,0)))+IF(R27>=50,10,IF(R27>=40,6,IF(R27>=30,3,0)))+IF(S27>=45,15,IF(S27>=40,12,IF(S27>=35,8,IF(S27>=30,4,0))))+IF(T27>=10000,10,IF(T27>=8000,7,IF(T27>=6000,4,0)))+IF(U27<>"",U27*5,0)+IF(V27<>"",V27*10,0)+IF(W27<>"",W27*8,0)+IF(X27>=66,10,IF(X27>=50,6,IF(X27>=33,3,0))) | AP27: =IF(AA27=1,5,0)+IF(AB27=1,5,0)+IF(AC27=1,5,0)+IF(AD27=1,5,0)+IF(AE27=1,5,0)+IF(AF27=1,5,0) | AQ27: =IF(AG27<>"",AG27*8,0)+IF(AH27<>"",AH27*5,0)+IF(AI27<>"",AI27*10,0)+IF(AJ27<>"",AJ27*3,0)+IF(AK27=1,5,0)+IF(AL27<>"",AL27*5,0) | AR27: =AM27+AN27+AO27+AP27+AQ27
A28: 25 | B28: Sun | AM28: =SUMPRODUCT((TRUNC(C28:G28))*10)+SUMPRODUCT(ROUND((C28:G28-TRUNC(C28:G28))*10,0)*5)+IF(H28="",0,H28*10) | AN28: =IF(AND(I28>=70,I28<=140),20,IF(AND(I28>140,I28<=180),10,0))+IF(J28>=70,15,IF(J28>=50,8,0))+IF(AND(K28>0,K28<=30),10,IF(AND(K28>30,K28<=50),5,0))+IF(L28=0,10,0)+IF(M28>0,5,0)+IF(N28<>"",N28*2,0) | AO28: =IF(AND(O28>=7,O28<=8),15,IF(AND(O28>=6,O28<7),8,IF(O28>8,10,0)))+IF(P28>=80,10,IF(P28>=70,6,IF(P28>=60,3,0)))+IF(Q28<=60,15,IF(Q28<=70,10,IF(Q28<=80,5,0)))+IF(R28>=50,10,IF(R28>=40,6,IF(R28>=30,3,0)))+IF(S28>=45,15,IF(S28>=40,12,IF(S28>=35,8,IF(S28>=30,4,0))))+IF(T28>=10000,10,IF(T28>=8000,7,IF(T28>=6000,4,0)))+IF(U28<>"",U28*5,0)+IF(V28<>"",V28*10,0)+IF(W28<>"",W28*8,0)+IF(X28>=66,10,IF(X28>=50,6,IF(X28>=33,3,0))) | AP28: =IF(AA28=1,5,0)+IF(AB28=1,5,0)+IF(AC28=1,5,0)+IF(AD28=1,5,0)+IF(AE28=1,5,0)+IF(AF28=1,5,0) | AQ28: =IF(AG28<>"",AG28*8,0)+IF(AH28<>"",AH28*5,0)+IF(AI28<>"",AI28*10,0)+IF(AJ28<>"",AJ28*3,0)+IF(AK28=1,5,0)+IF(AL28<>"",AL28*5,0) | AR28: =AM28+AN28+AO28+AP28+AQ28
A29: 26 | B29: Mon | AM29: =SUMPRODUCT((TRUNC(C29:G29))*10)+SUMPRODUCT(ROUND((C29:G29-TRUNC(C29:G29))*10,0)*5)+IF(H29="",0,H29*10) | AN29: =IF(AND(I29>=70,I29<=140),20,IF(AND(I29>140,I29<=180),10,0))+IF(J29>=70,15,IF(J29>=50,8,0))+IF(AND(K29>0,K29<=30),10,IF(AND(K29>30,K29<=50),5,0))+IF(L29=0,10,0)+IF(M29>0,5,0)+IF(N29<>"",N29*2,0) | AO29: =IF(AND(O29>=7,O29<=8),15,IF(AND(O29>=6,O29<7),8,IF(O29>8,10,0)))+IF(P29>=80,10,IF(P29>=70,6,IF(P29>=60,3,0)))+IF(Q29<=60,15,IF(Q29<=70,10,IF(Q29<=80,5,0)))+IF(R29>=50,10,IF(R29>=40,6,IF(R29>=30,3,0)))+IF(S29>=45,15,IF(S29>=40,12,IF(S29>=35,8,IF(S29>=30,4,0))))+IF(T29>=10000,10,IF(T29>=8000,7,IF(T29>=6000,4,0)))+IF(U29<>"",U29*5,0)+IF(V29<>"",V29*10,0)+IF(W29<>"",W29*8,0)+IF(X29>=66,10,IF(X29>=50,6,IF(X29>=33,3,0))) | AP29: =IF(AA29=1,5,0)+IF(AB29=1,5,0)+IF(AC29=1,5,0)+IF(AD29=1,5,0)+IF(AE29=1,5,0)+IF(AF29=1,5,0) | AQ29: =IF(AG29<>"",AG29*8,0)+IF(AH29<>"",AH29*5,0)+IF(AI29<>"",AI29*10,0)+IF(AJ29<>"",AJ29*3,0)+IF(AK29=1,5,0)+IF(AL29<>"",AL29*5,0) | AR29: =AM29+AN29+AO29+AP29+AQ29
A30: 27 | B30: Tue | AM30: =SUMPRODUCT((TRUNC(C30:G30))*10)+SUMPRODUCT(ROUND((C30:G30-TRUNC(C30:G30))*10,0)*5)+IF(H30="",0,H30*10) | AN30: =IF(AND(I30>=70,I30<=140),20,IF(AND(I30>140,I30<=180),10,0))+IF(J30>=70,15,IF(J30>=50,8,0))+IF(AND(K30>0,K30<=30),10,IF(AND(K30>30,K30<=50),5,0))+IF(L30=0,10,0)+IF(M30>0,5,0)+IF(N30<>"",N30*2,0) | AO30: =IF(AND(O30>=7,O30<=8),15,IF(AND(O30>=6,O30<7),8,IF(O30>8,10,0)))+IF(P30>=80,10,IF(P30>=70,6,IF(P30>=60,3,0)))+IF(Q30<=60,15,IF(Q30<=70,10,IF(Q30<=80,5,0)))+IF(R30>=50,10,IF(R30>=40,6,IF(R30>=30,3,0)))+IF(S30>=45,15,IF(S30>=40,12,IF(S30>=35,8,IF(S30>=30,4,0))))+IF(T30>=10000,10,IF(T30>=8000,7,IF(T30>=6000,4,0)))+IF(U30<>"",U30*5,0)+IF(V30<>"",V30*10,0)+IF(W30<>"",W30*8,0)+IF(X30>=66,10,IF(X30>=50,6,IF(X30>=33,3,0))) | AP30: =IF(AA30=1,5,0)+IF(AB30=1,5,0)+IF(AC30=1,5,0)+IF(AD30=1,5,0)+IF(AE30=1,5,0)+IF(AF30=1,5,0) | AQ30: =IF(AG30<>"",AG30*8,0)+IF(AH30<>"",AH30*5,0)+IF(AI30<>"",AI30*10,0)+IF(AJ30<>"",AJ30*3,0)+IF(AK30=1,5,0)+IF(AL30<>"",AL30*5,0) | AR30: =AM30+AN30+AO30+AP30+AQ30
A31: 28 | B31: Wed | AM31: =SUMPRODUCT((TRUNC(C31:G31))*10)+SUMPRODUCT(ROUND((C31:G31-TRUNC(C31:G31))*10,0)*5)+IF(H31="",0,H31*10) | AN31: =IF(AND(I31>=70,I31<=140),20,IF(AND(I31>140,I31<=180),10,0))+IF(J31>=70,15,IF(J31>=50,8,0))+IF(AND(K31>0,K31<=30),10,IF(AND(K31>30,K31<=50),5,0))+IF(L31=0,10,0)+IF(M31>0,5,0)+IF(N31<>"",N31*2,0) | AO31: =IF(AND(O31>=7,O31<=8),15,IF(AND(O31>=6,O31<7),8,IF(O31>8,10,0)))+IF(P31>=80,10,IF(P31>=70,6,IF(P31>=60,3,0)))+IF(Q31<=60,15,IF(Q31<=70,10,IF(Q31<=80,5,0)))+IF(R31>=50,10,IF(R31>=40,6,IF(R31>=30,3,0)))+IF(S31>=45,15,IF(S31>=40,12,IF(S31>=35,8,IF(S31>=30,4,0))))+IF(T31>=10000,10,IF(T31>=8000,7,IF(T31>=6000,4,0)))+IF(U31<>"",U31*5,0)+IF(V31<>"",V31*10,0)+IF(W31<>"",W31*8,0)+IF(X31>=66,10,IF(X31>=50,6,IF(X31>=33,3,0))) | AP31: =IF(AA31=1,5,0)+IF(AB31=1,5,0)+IF(AC31=1,5,0)+IF(AD31=1,5,0)+IF(AE31=1,5,0)+IF(AF31=1,5,0) | AQ31: =IF(AG31<>"",AG31*8,0)+IF(AH31<>"",AH31*5,0)+IF(AI31<>"",AI31*10,0)+IF(AJ31<>"",AJ31*3,0)+IF(AK31=1,5,0)+IF(AL31<>"",AL31*5,0) | AR31: =AM31+AN31+AO31+AP31+AQ31
A32: 29 | B32: Thu | AM32: =SUMPRODUCT((TRUNC(C32:G32))*10)+SUMPRODUCT(ROUND((C32:G32-TRUNC(C32:G32))*10,0)*5)+IF(H32="",0,H32*10) | AN32: =IF(AND(I32>=70,I32<=140),20,IF(AND(I32>140,I32<=180),10,0))+IF(J32>=70,15,IF(J32>=50,8,0))+IF(AND(K32>0,K32<=30),10,IF(AND(K32>30,K32<=50),5,0))+IF(L32=0,10,0)+IF(M32>0,5,0)+IF(N32<>"",N32*2,0) | AO32: =IF(AND(O32>=7,O32<=8),15,IF(AND(O32>=6,O32<7),8,IF(O32>8,10,0)))+IF(P32>=80,10,IF(P32>=70,6,IF(P32>=60,3,0)))+IF(Q32<=60,15,IF(Q32<=70,10,IF(Q32<=80,5,0)))+IF(R32>=50,10,IF(R32>=40,6,IF(R32>=30,3,0)))+IF(S32>=45,15,IF(S32>=40,12,IF(S32>=35,8,IF(S32>=30,4,0))))+IF(T32>=10000,10,IF(T32>=8000,7,IF(T32>=6000,4,0)))+IF(U32<>"",U32*5,0)+IF(V32<>"",V32*10,0)+IF(W32<>"",W32*8,0)+IF(X32>=66,10,IF(X32>=50,6,IF(X32>=33,3,0))) | AP32: =IF(AA32=1,5,0)+IF(AB32=1,5,0)+IF(AC32=1,5,0)+IF(AD32=1,5,0)+IF(AE32=1,5,0)+IF(AF32=1,5,0) | AQ32: =IF(AG32<>"",AG32*8,0)+IF(AH32<>"",AH32*5,0)+IF(AI32<>"",AI32*10,0)+IF(AJ32<>"",AJ32*3,0)+IF(AK32=1,5,0)+IF(AL32<>"",AL32*5,0) | AR32: =AM32+AN32+AO32+AP32+AQ32
A33: 30 | B33: Fri | AM33: =SUMPRODUCT((TRUNC(C33:G33))*10)+SUMPRODUCT(ROUND((C33:G33-TRUNC(C33:G33))*10,0)*5)+IF(H33="",0,H33*10) | AN33: =IF(AND(I33>=70,I33<=140),20,IF(AND(I33>140,I33<=180),10,0))+IF(J33>=70,15,IF(J33>=50,8,0))+IF(AND(K33>0,K33<=30),10,IF(AND(K33>30,K33<=50),5,0))+IF(L33=0,10,0)+IF(M33>0,5,0)+IF(N33<>"",N33*2,0) | AO33: =IF(AND(O33>=7,O33<=8),15,IF(AND(O33>=6,O33<7),8,IF(O33>8,10,0)))+IF(P33>=80,10,IF(P33>=70,6,IF(P33>=60,3,0)))+IF(Q33<=60,15,IF(Q33<=70,10,IF(Q33<=80,5,0)))+IF(R33>=50,10,IF(R33>=40,6,IF(R33>=30,3,0)))+IF(S33>=45,15,IF(S33>=40,12,IF(S33>=35,8,IF(S33>=30,4,0))))+IF(T33>=10000,10,IF(T33>=8000,7,IF(T33>=6000,4,0)))+IF(U33<>"",U33*5,0)+IF(V33<>"",V33*10,0)+IF(W33<>"",W33*8,0)+IF(X33>=66,10,IF(X33>=50,6,IF(X33>=33,3,0))) | AP33: =IF(AA33=1,5,0)+IF(AB33=1,5,0)+IF(AC33=1,5,0)+IF(AD33=1,5,0)+IF(AE33=1,5,0)+IF(AF33=1,5,0) | AQ33: =IF(AG33<>"",AG33*8,0)+IF(AH33<>"",AH33*5,0)+IF(AI33<>"",AI33*10,0)+IF(AJ33<>"",AJ33*3,0)+IF(AK33=1,5,0)+IF(AL33<>"",AL33*5,0) | AR33: =AM33+AN33+AO33+AP33+AQ33
A34: 31 | B34: Sat | AM34: =SUMPRODUCT((TRUNC(C34:G34))*10)+SUMPRODUCT(ROUND((C34:G34-TRUNC(C34:G34))*10,0)*5)+IF(H34="",0,H34*10) | AN34: =IF(AND(I34>=70,I34<=140),20,IF(AND(I34>140,I34<=180),10,0))+IF(J34>=70,15,IF(J34>=50,8,0))+IF(AND(K34>0,K34<=30),10,IF(AND(K34>30,K34<=50),5,0))+IF(L34=0,10,0)+IF(M34>0,5,0)+IF(N34<>"",N34*2,0) | AO34: =IF(AND(O34>=7,O34<=8),15,IF(AND(O34>=6,O34<7),8,IF(O34>8,10,0)))+IF(P34>=80,10,IF(P34>=70,6,IF(P34>=60,3,0)))+IF(Q34<=60,15,IF(Q34<=70,10,IF(Q34<=80,5,0)))+IF(R34>=50,10,IF(R34>=40,6,IF(R34>=30,3,0)))+IF(S34>=45,15,IF(S34>=40,12,IF(S34>=35,8,IF(S34>=30,4,0))))+IF(T34>=10000,10,IF(T34>=8000,7,IF(T34>=6000,4,0)))+IF(U34<>"",U34*5,0)+IF(V34<>"",V34*10,0)+IF(W34<>"",W34*8,0)+IF(X34>=66,10,IF(X34>=50,6,IF(X34>=33,3,0))) | AP34: =IF(AA34=1,5,0)+IF(AB34=1,5,0)+IF(AC34=1,5,0)+IF(AD34=1,5,0)+IF(AE34=1,5,0)+IF(AF34=1,5,0) | AQ34: =IF(AG34<>"",AG34*8,0)+IF(AH34<>"",AH34*5,0)+IF(AI34<>"",AI34*10,0)+IF(AJ34<>"",AJ34*3,0)+IF(AK34=1,5,0)+IF(AL34<>"",AL34*5,0) | AR34: =AM34+AN34+AO34+AP34+AQ34

Sheet Feb 2026
A1: Info | C1: 🕌 Prayers | I1: 💉 Glucose | O1: ⏱️ Whoop Age | AA1: 👨‍👩‍👧‍👦 Family | AG1: ✨ Habits | AM1: 📊 Scores
A2: Day | B2: Date | C2: Fajr | D2: Dhuhr | E2: Asr | F2: Maghrib | G2: Isha | H2: 📖 Quran | I2: Avg | J2: TIR% | K2: CV% | L2: Hypos | M2: Insulin | N2: NoP | O2: Sleep | P2: Consist | Q2: RHR | R2: HRV | S2: VO2 | T2: Steps | U2: Zone1-3 | V2: Zone4-5 | W2: Strength | X2: Recovery | Y2: Strain | Z2: Age | AA2: 👩 Mom | AB2: 👨 Dad | AC2: 👧 Jana | AD2: 👶 Tia | AE2: 👦 Ahmed | AF2: 👩‍🦱 Eman | AG2: 🏋️ | AH2: 📚 | AI2: 🧘 | AJ2: 💧 | AK2: 💊 | AL2: 🦷 | AM2: Prayer | AN2: Health | AO2: Whoop | AP2: Family | AQ2: Habit | AR2: TOTAL
AA3: (5 pts) | AB3: (5 pts) | AC3: (5 pts) | AD3: (5 pts) | AE3: (5 pts) | AF3: (5 pts)
A4: 1 | B4: Sun | AM4: =SUMPRODUCT((TRUNC(C4:G4))*10)+SUMPRODUCT(ROUND((C4:G4-TRUNC(C4:G4))*10,0)*5)+IF(H4="",0,H4*10) | AN4: =IF(AND(I4>=70,I4<=140),20,IF(AND(I4>140,I4<=180),10,0))+IF(J4>=70,15,IF(J4>=50,8,0))+IF(AND(K4>0,K4<=30),10,IF(AND(K4>30,K4<=50),5,0))+IF(L4=0,10,0)+IF(M4>0,5,0)+IF(N4<>"",N4*2,0) | AO4: =IF(AND(O4>=7,O4<=8),15,IF(AND(O4>=6,O4<7),8,IF(O4>8,10,0)))+IF(P4>=80,10,IF(P4>=70,6,IF(P4>=60,3,0)))+IF(Q4<=60,15,IF(Q4<=70,10,IF(Q4<=80,5,0)))+IF(R4>=50,10,IF(R4>=40,6,IF(R4>=30,3,0)))+IF(S4>=45,15,IF(S4>=40,12,IF(S4>=35,8,IF(S4>=30,4,0))))+IF(T4>=10000,10,IF(T4>=8000,7,IF(T4>=6000,4,0)))+IF(U4<>"",U4*5,0)+IF(V4<>"",V4*10,0)+IF(W4<>"",W4*8,0)+IF(X4>=66,10,IF(X4>=50,6,IF(X4>=33,3,0))) | AP4: =IF(AA4=1,5,0)+IF(AB4=1,5,0)+IF(AC4=1,5,0)+IF(AD4=1,5,0)+IF(AE4=1,5,0)+IF(AF4=1,5,0) | AQ4: =IF(AG4<>"",AG4*8,0)+IF(AH4<>"",AH4*5,0)+IF(AI4<>"",AI4*10,0)+IF(AJ4<>"",AJ4*3,0)+IF(AK4=1,5,0)+IF(AL4<>"",AL4*5,0) | AR4: =AM4+AN4+AO4+AP4+AQ4
A5: 2 | B5: Mon | AM5: =SUMPRODUCT((TRUNC(C5:G5))*10)+SUMPRODUCT(ROUND((C5:G5-TRUNC(C5:G5))*10,0)*5)+IF(H5="",0,H5*10) | AN5: =IF(AND(I5>=70,I5<=140),20,IF(AND(I5>140,I5<=180),10,0))+IF(J5>=70,15,IF(J5>=50,8,0))+IF(AND(K5>0,K5<=30),10,IF(AND(K5>30,K5<=50),5,0))+IF(L5=0,10,0)+IF(M5>0,5,0)+IF(N5<>"",N5*2,0) | AO5: =IF(AND(O5>=7,O5<=8),15,IF(AND(O5>=6,O5<7),8,IF(O5>8,10,0)))+IF(P5>=80,10,IF(P5>=70,6,IF(P5>=60,3,0)))+IF(Q5<=60,15,IF(Q5<=70,10,IF(Q5<=80,5,0)))+IF(R5>=50,10,IF(R5>=40,6,IF(R5>=30,3,0)))+IF(S5>=45,15,IF(S5>=40,12,IF(S5>=35,8,IF(S5>=30,4,0))))+IF(T5>=10000,10,IF(T5>=8000,7,IF(T5>=6000,4,0)))+IF(U5<>"",U5*5,0)+IF(V5<>"",V5*10,0)+IF(W5<>"",W5*8,0)+IF(X5>=66,10,IF(X5>=50,6,IF(X5>=33,3,0))) | AP5: =IF(AA5=1,5,0)+IF(AB5=1,5,0)+IF(AC5=1,5,0)+IF(AD5=1,5,0)+IF(AE5=1,5,0)+IF(AF5=1,5,0) | AQ5: =IF(AG5<>"",AG5*8,0)+IF(AH5<>"",AH5*5,0)+IF(AI5<>"",AI5*10,0)+IF(AJ5<>"",AJ5*3,0)+IF(AK5=1,5,0)+IF(AL5<>"",AL5*5,0) | AR5: =AM5+AN5+AO5+AP5+AQ5
A6: 3 | B6: Tue | AM6: =SUMPRODUCT((TRUNC(C6:G6))*10)+SUMPRODUCT(ROUND((C6:G6-TRUNC(C6:G6))*10,0)*5)+IF(H6="",0,H6*10) | AN6: =IF(AND(I6>=70,I6<=140),20,IF(AND(I6>140,I6<=180),10,0))+IF(J6>=70,15,IF(J6>=50,8,0))+IF(AND(K6>0,K6<=30),10,IF(AND(K6>30,K6<=50),5,0))+IF(L6=0,10,0)+IF(M6>0,5,0)+IF(N6<>"",N6*2,0) | AO6: =IF(AND(O6>=7,O6<=8),15,IF(AND(O6>=6,O6<7),8,IF(O6>8,10,0)))+IF(P6>=80,10,IF(P6>=70,6,IF(P6>=60,3,0)))+IF(Q6<=60,15,IF(Q6<=70,10,IF(Q6<=80,5,0)))+IF(R6>=50,10,IF(R6>=40,6,IF(R6>=30,3,0)))+IF(S6>=45,15,IF(S6>=40,12,IF(S6>=35,8,IF(S6>=30,4,0))))+IF(T6>=10000,10,IF(T6>=8000,7,IF(T6>=6000,4,0)))+IF(U6<>"",U6*5,0)+IF(V6<>"",V6*10,0)+IF(W6<>"",W6*8,0)+IF(X6>=66,10,IF(X6>=50,6,IF(X6>=33,3,0))) | AP6: =IF(AA6=1,5,0)+IF(AB6=1,5,0)+IF(AC6=1,5,0)+IF(AD6=1,5,0)+IF(AE6=1,5,0)+IF(AF6=1,5,0) | AQ6: =IF(AG6<>"",AG6*8,0)+IF(AH6<>"",AH6*5,0)+IF(AI6<>"",AI6*10,0)+IF(AJ6<>"",AJ6*3,0)+IF(AK6=1,5,0)+IF(AL6<>"",AL6*5,0) | AR6: =AM6+AN6+AO6+AP6+AQ6
A7: 4 | B7: Wed | AM7: =SUMPRODUCT((TRUNC(C7:G7))*10)+SUMPRODUCT(ROUND((C7:G7-TRUNC(C7:G7))*10,0)*5)+IF(H7="",0,H7*10) | AN7: =IF(AND(I7>=70,I7<=140),20,IF(AND(I7>140,I7<=180),10,0))+IF(J7>=70,15,IF(J7>=50,8,0))+IF(AND(K7>0,K7<=30),10,IF(AND(K7>30,K7<=50),5,0))+IF(L7=0,10,0)+IF(M7>0,5,0)+IF(N7<>"",N7*2,0) | AO7: =IF(AND(O7>=7,O7<=8),15,IF(AND(O7>=6,O7<7),8,IF(O7>8,10,0)))+IF(P7>=80,10,IF(P7>=70,6,IF(P7>=60,3,0)))+IF(Q7<=60,15,IF(Q7<=70,10,IF(Q7<=80,5,0)))+IF(R7>=50,10,IF(R7>=40,6,IF(R7>=30,3,0)))+IF(S7>=45,15,IF(S7>=40,12,IF(S7>=35,8,IF(S7>=30,4,0))))+IF(T7>=10000,10,IF(T7>=8000,7,IF(T7>=6000,4,0)))+IF(U7<>"",U7*5,0)+IF(V7<>"",V7*10,0)+IF(W7<>"",W7*8,0)+IF(X7>=66,10,IF(X7>=50,6,IF(X7>=33,3,0))) | AP7: =IF(AA7=1,5,0)+IF(AB7=1,5,0)+IF(AC7=1,5,0)+IF(AD7=1,5,0)+IF(AE7=1,5,0)+IF(AF7=1,5,0) | AQ7: =IF(AG7<>"",AG7*8,0)+IF(AH7<>"",AH7*5,0)+IF(AI7<>"",AI7*10,0)+IF(AJ7<>"",AJ7*3,0)+IF(AK7=1,5,0)+IF(AL7<>"",AL7*5,0) | AR7: =AM7+AN7+AO7+AP7+AQ7
A8: 5 | B8: Thu | AM8: =SUMPRODUCT((TRUNC(C8:G8))*10)+SUMPRODUCT(ROUND((C8:G8-TRUNC(C8:G8))*10,0)*5)+IF(H8="",0,H8*10) | AN8: =IF(AND(I8>=70,I8<=140),20,IF(AND(I8>140,I8<=180),10,0))+IF(J8>=70,15,IF(J8>=50,8,0))+IF(AND(K8>0,K8<=30),10,IF(AND(K8>30,K8<=50),5,0))+IF(L8=0,10,0)+IF(M8>0,5,0)+IF(N8<>"",N8*2,0) | AO8: =IF(AND(O8>=7,O8<=8),15,IF(AND(O8>=6,O8<7),8,IF(O8>8,10,0)))+IF(P8>=80,10,IF(P8>=70,6,IF(P8>=60,3,0)))+IF(Q8<=60,15,IF(Q8<=70,10,IF(Q8<=80,5,0)))+IF(R8>=50,10,IF(R8>=40,6,IF(R8>=30,3,0)))+IF(S8>=45,15,IF(S8>=40,12,IF(S8>=35,8,IF(S8>=30,4,0))))+IF(T8>=10000,10,IF(T8>=8000,7,IF(T8>=6000,4,0)))+IF(U8<>"",U8*5,0)+IF(V8<>"",V8*10,0)+IF(W8<>"",W8*8,0)+IF(X8>=66,10,IF(X8>=50,6,IF(X8>=33,3,0))) | AP8: =IF(AA8=1,5,0)+IF(AB8=1,5,0)+IF(AC8=1,5,0)+IF(AD8=1,5,0)+IF(AE8=1,5,0)+IF(AF8=1,5,0) | AQ8: =IF(AG8<>"",AG8*8,0)+IF(AH8<>"",AH8*5,0)+IF(AI8<>"",AI8*10,0)+IF(AJ8<>"",AJ8*3,0)+IF(AK8=1,5,0)+IF(AL8<>"",AL8*5,0) | AR8: =AM8+AN8+AO8+AP8+AQ8
A9: 6 | B9: Fri | AM9: =SUMPRODUCT((TRUNC(C9:G9))*10)+SUMPRODUCT(ROUND((C9:G9-TRUNC(C9:G9))*10,0)*5)+IF(H9="",0,H9*10) | AN9: =IF(AND(I9>=70,I9<=140),20,IF(AND(I9>140,I9<=180),10,0))+IF(J9>=70,15,IF(J9>=50,8,0))+IF(AND(K9>0,K9<=30),10,IF(AND(K9>30,K9<=50),5,0))+IF(L9=0,10,0)+IF(M9>0,5,0)+IF(N9<>"",N9*2,0) | AO9: =IF(AND(O9>=7,O9<=8),15,IF(AND(O9>=6,O9<7),8,IF(O9>8,10,0)))+IF(P9>=80,10,IF(P9>=70,6,IF(P9>=60,3,0)))+IF(Q9<=60,15,IF(Q9<=70,10,IF(Q9<=80,5,0)))+IF(R9>=50,10,IF(R9>=40,6,IF(R9>=30,3,0)))+IF(S9>=45,15,IF(S9>=40,12,IF(S9>=35,8,IF(S9>=30,4,0))))+IF(T9>=10000,10,IF(T9>=8000,7,IF(T9>=6000,4,0)))+IF(U9<>"",U9*5,0)+IF(V9<>"",V9*10,0)+IF(W9<>"",W9*8,0)+IF(X9>=66,10,IF(X9>=50,6,IF(X9>=33,3,0))) | AP9: =IF(AA9=1,5,0)+IF(AB9=1,5,0)+IF(AC9=1,5,0)+IF(AD9=1,5,0)+IF(AE9=1,5,0)+IF(AF9=1,5,0) | AQ9: =IF(AG9<>"",AG9*8,0)+IF(AH9<>"",AH9*5,0)+IF(AI9<>"",AI9*10,0)+IF(AJ9<>"",AJ9*3,0)+IF(AK9=1,5,0)+IF(AL9<>"",AL9*5,0) | AR9: =AM9+AN9+AO9+AP9+AQ9
A10: 7 | B10: Sat | AM10: =SUMPRODUCT((TRUNC(C10:G10))*10)+SUMPRODUCT(ROUND((C10:G10-TRUNC(C10:G10))*10,0)*5)+IF(H10="",0,H10*10) | AN10: =IF(AND(I10>=70,I10<=140),20,IF(AND(I10>140,I10<=180),10,0))+IF(J10>=70,15,IF(J10>=50,8,0))+IF(AND(K10>0,K10<=30),10,IF(AND(K10>30,K10<=50),5,0))+IF(L10=0,10,0)+IF(M10>0,5,0)+IF(N10<>"",N10*2,0) | AO10: =IF(AND(O10>=7,O10<=8),15,IF(AND(O10>=6,O10<7),8,IF(O10>8,10,0)))+IF(P10>=80,10,IF(P10>=70,6,IF(P10>=60,3,0)))+IF(Q10<=60,15,IF(Q10<=70,10,IF(Q10<=80,5,0)))+IF(R10>=50,10,IF(R10>=40,6,IF(R10>=30,3,0)))+IF(S10>=45,15,IF(S10>=40,12,IF(S10>=35,8,IF(S10>=30,4,0))))+IF(T10>=10000,10,IF(T10>=8000,7,IF(T10>=6000,4,0)))+IF(U10<>"",U10*5,0)+IF(V10<>"",V10*10,0)+IF(W10<>"",W10*8,0)+IF(X10>=66,10,IF(X10>=50,6,IF(X10>=33,3,0))) | AP10: =IF(AA10=1,5,0)+IF(AB10=1,5,0)+IF(AC10=1,5,0)+IF(AD10=1,5,0)+IF(AE10=1,5,0)+IF(AF10=1,5,0) | AQ10: =IF(AG10<>"",AG10*8,0)+IF(AH10<>"",AH10*5,0)+IF(AI10<>"",AI10*10,0)+IF(AJ10<>"",AJ10*3,0)+IF(AK10=1,5,0)+IF(AL10<>"",AL10*5,0) | AR10: =AM10+AN10+AO10+AP10+AQ10
A11: 8 | B11: Sun | AM11: =SUMPRODUCT((TRUNC(C11:G11))*10)+SUMPRODUCT(ROUND((C11:G11-TRUNC(C11:G11))*10,0)*5)+IF(H11="",0,H11*10) | AN11: =IF(AND(I11>=70,I11<=140),20,IF(AND(I11>140,I11<=180),10,0))+IF(J11>=70,15,IF(J11>=50,8,0))+IF(AND(K11>0,K11<=30),10,IF(AND(K11>30,K11<=50),5,0))+IF(L11=0,10,0)+IF(M11>0,5,0)+IF(N11<>"",N11*2,0) | AO11: =IF(AND(O11>=7,O11<=8),15,IF(AND(O11>=6,O11<7),8,IF(O11>8,10,0)))+IF(P11>=80,10,IF(P11>=70,6,IF(P11>=60,3,0)))+IF(Q11<=60,15,IF(Q11<=70,10,IF(Q11<=80,5,0)))+IF(R11>=50,10,IF(R11>=40,6,IF(R11>=30,3,0)))+IF(S11>=45,15,IF(S11>=40,12,IF(S11>=35,8,IF(S11>=30,4,0))))+IF(T11>=10000,10,IF(T11>=8000,7,IF(T11>=6000,4,0)))+IF(U11<>"",U11*5,0)+IF(V11<>"",V11*10,0)+IF(W11<>"",W11*8,0)+IF(X11>=66,10,IF(X11>=50,6,IF(X11>=33,3,0))) | AP11: =IF(AA11=1,5,0)+IF(AB11=1,5,0)+IF(AC11=1,5,0)+IF(AD11=1,5,0)+IF(AE11=1,5,0)+IF(AF11=1,5,0) | AQ11: =IF(AG11<>"",AG11*8,0)+IF(AH11<>"",AH11*5,0)+IF(AI11<>"",AI11*10,0)+IF(AJ11<>"",AJ11*3,0)+IF(AK11=1,5,0)+IF(AL11<>"",AL11*5,0) | AR11: =AM11+AN11+AO11+AP11+AQ11
A12: 9 | B12: Mon | AM12: =SUMPRODUCT((TRUNC(C12:G12))*10)+SUMPRODUCT(ROUND((C12:G12-TRUNC(C12:G12))*10,0)*5)+IF(H12="",0,H12*10) | AN12: =IF(AND(I12>=70,I12<=140),20,IF(AND(I12>140,I12<=180),10,0))+IF(J12>=70,15,IF(J12>=50,8,0))+IF(AND(K12>0,K12<=30),10,IF(AND(K12>30,K12<=50),5,0))+IF(L12=0,10,0)+IF(M12>0,5,0)+IF(N12<>"",N12*2,0) | AO12: =IF(AND(O12>=7,O12<=8),15,IF(AND(O12>=6,O12<7),8,IF(O12>8,10,0)))+IF(P12>=80,10,IF(P12>=70,6,IF(P12>=60,3,0)))+IF(Q12<=60,15,IF(Q12<=70,10,IF(Q12<=80,5,0)))+IF(R12>=50,10,IF(R12>=40,6,IF(R12>=30,3,0)))+IF(S12>=45,15,IF(S12>=40,12,IF(S12>=35,8,IF(S12>=30,4,0))))+IF(T12>=10000,10,IF(T12>=8000,7,IF(T12>=6000,4,0)))+IF(U12<>"",U12*5,0)+IF(V12<>"",V12*10,0)+IF(W12<>"",W12*8,0)+IF(X12>=66,10,IF(X12>=50,6,IF(X12>=33,3,0))) | AP12: =IF(AA12=1,5,0)+IF(AB12=1,5,0)+IF(AC12=1,5,0)+IF(AD12=1,5,0)+IF(AE12=1,5,0)+IF(AF12=1,5,0) | AQ12: =IF(AG12<>"",AG12*8,0)+IF(AH12<>"",AH12*5,0)+IF(AI12<>"",AI12*10,0)+IF(AJ12<>"",AJ12*3,0)+IF(AK12=1,5,0)+IF(AL12<>"",AL12*5,0) | AR12: =AM12+AN12+AO12+AP12+AQ12
A13: 10 | B13: Tue | AM13: =SUMPRODUCT((TRUNC(C13:G13))*10)+SUMPRODUCT(ROUND((C13:G13-TRUNC(C13:G13))*10,0)*5)+IF(H13="",0,H13*10) | AN13: =IF(AND(I13>=70,I13<=140),20,IF(AND(I13>140,I13<=180),10,0))+IF(J13>=70,15,IF(J13>=50,8,0))+IF(AND(K13>0,K13<=30),10,IF(AND(K13>30,K13<=50),5,0))+IF(L13=0,10,0)+IF(M13>0,5,0)+IF(N13<>"",N13*2,0) | AO13: =IF(AND(O13>=7,O13<=8),15,IF(AND(O13>=6,O13<7),8,IF(O13>8,10,0)))+IF(P13>=80,10,IF(P13>=70,6,IF(P13>=60,3,0)))+IF(Q13<=60,15,IF(Q13<=70,10,IF(Q13<=80,5,0)))+IF(R13>=50,10,IF(R13>=40,6,IF(R13>=30,3,0)))+IF(S13>=45,15,IF(S13>=40,12,IF(S13>=35,8,IF(S13>=30,4,0))))+IF(T13>=10000,10,IF(T13>=8000,7,IF(T13>=6000,4,0)))+IF(U13<>"",U13*5,0)+IF(V13<>"",V13*10,0)+IF(W13<>"",W13*8,0)+IF(X13>=66,10,IF(X13>=50,6,IF(X13>=33,3,0))) | AP13: =IF(AA13=1,5,0)+IF(AB13=1,5,0)+IF(AC13=1,5,0)+IF(AD13=1,5,0)+IF(AE13=1,5,0)+IF(AF13=1,5,0) | AQ13: =IF(AG13<>"",AG13*8,0)+IF(AH13<>"",AH13*5,0)+IF(AI13<>"",AI13*10,0)+IF(AJ13<>"",AJ13*3,0)+IF(AK13=1,5,0)+IF(AL13<>"",AL13*5,0) | AR13: =AM13+AN13+AO13+AP13+AQ13
A14: 11 | B14: Wed | AM14: =SUMPRODUCT((TRUNC(C14:G14))*10)+SUMPRODUCT(ROUND((C14:G14-TRUNC(C14:G14))*10,0)*5)+IF(H14="",0,H14*10) | AN14: =IF(AND(I14>=70,I14<=140),20,IF(AND(I14>140,I14<=180),10,0))+IF(J14>=70,15,IF(J14>=50,8,0))+IF(AND(K14>0,K14<=30),10,IF(AND(K14>30,K14<=50),5,0))+IF(L14=0,10,0)+IF(M14>0,5,0)+IF(N14<>"",N14*2,0) | AO14: =IF(AND(O14>=7,O14<=8),15,IF(AND(O14>=6,O14<7),8,IF(O14>8,10,0)))+IF(P14>=80,10,IF(P14>=70,6,IF(P14>=60,3,0)))+IF(Q14<=60,15,IF(Q14<=70,10,IF(Q14<=80,5,0)))+IF(R14>=50,10,IF(R14>=40,6,IF(R14>=30,3,0)))+IF(S14>=45,15,IF(S14>=40,12,IF(S14>=35,8,IF(S14>=30,4,0))))+IF(T14>=10000,10,IF(T14>=8000,7,IF(T14>=6000,4,0)))+IF(U14<>"",U14*5,0)+IF(V14<>"",V14*10,0)+IF(W14<>"",W14*8,0)+IF(X14>=66,10,IF(X14>=50,6,IF(X14>=33,3,0))) | AP14: =IF(AA14=1,5,0)+IF(AB14=1,5,0)+IF(AC14=1,5,0)+IF(AD14=1,5,0)+IF(AE14=1,5,0)+IF(AF14=1,5,0) | AQ14: =IF(AG14<>"",AG14*8,0)+IF(AH14<>"",AH14*5,0)+IF(AI14<>"",AI14*10,0)+IF(AJ14<>"",AJ14*3,0)+IF(AK14=1,5,0)+IF(AL14<>"",AL14*5,0) | AR14: =AM14+AN14+AO14+AP14+AQ14
A15: 12 | B15: Thu | AM15: =SUMPRODUCT((TRUNC(C15:G15))*10)+SUMPRODUCT(ROUND((C15:G15-TRUNC(C15:G15))*10,0)*5)+IF(H15="",0,H15*10) | AN15: =IF(AND(I15>=70,I15<=140),20,IF(AND(I15>140,I15<=180),10,0))+IF(J15>=70,15,IF(J15>=50,8,0))+IF(AND(K15>0,K15<=30),10,IF(AND(K15>30,K15<=50),5,0))+IF(L15=0,10,0)+IF(M15>0,5,0)+IF(N15<>"",N15*2,0) | AO15: =IF(AND(O15>=7,O15<=8),15,IF(AND(O15>=6,O15<7),8,IF(O15>8,10,0)))+IF(P15>=80,10,IF(P15>=70,6,IF(P15>=60,3,0)))+IF(Q15<=60,15,IF(Q15<=70,10,IF(Q15<=80,5,0)))+IF(R15>=50,10,IF(R15>=40,6,IF(R15>=30,3,0)))+IF(S15>=45,15,IF(S15>=40,12,IF(S15>=35,8,IF(S15>=30,4,0))))+IF(T15>=10000,10,IF(T15>=8000,7,IF(T15>=6000,4,0)))+IF(U15<>"",U15*5,0)+IF(V15<>"",V15*10,0)+IF(W15<>"",W15*8,0)+IF(X15>=66,10,IF(X15>=50,6,IF(X15>=33,3,0))) | AP15: =IF(AA15=1,5,0)+IF(AB15=1,5,0)+IF(AC15=1,5,0)+IF(AD15=1,5,0)+IF(AE15=1,5,0)+IF(AF15=1,5,0) | AQ15: =IF(AG15<>"",AG15*8,0)+IF(AH15<>"",AH15*5,0)+IF(AI15<>"",AI15*10,0)+IF(AJ15<>"",AJ15*3,0)+IF(AK15=1,5,0)+IF(AL15<>"",AL15*5,0) | AR15: =AM15+AN15+AO15+AP15+AQ15
... A31: 28 | B31: Sat | AM31: =SUMPRODUCT((TRUNC(C31:G31))*10)+SUMPRODUCT(ROUND((C31:G31-TRUNC(C31:G31))*10,0)*5)+IF(H31="",0,H31*10) | AN31: =IF(AND(I31>=70,I31<=140),20,IF(AND(I31>140,I31<=180),10,0))+IF(J31>=70,15,IF(J31>=50,8,0))+IF(AND(K31>0,K31<=30),10,IF(AND(K31>30,K31<=50),5,0))+IF(L31=0,10,0)+IF(M31>0,5,0)+IF(N31<>"",N31*2,0) | AO31: =IF(AND(O31>=7,O31<=8),15,IF(AND(O31>=6,O31<7),8,IF(O31>8,10,0)))+IF(P31>=80,10,IF(P31>=70,6,IF(P31>=60,3,0)))+IF(Q31<=60,15,IF(Q31<=70,10,IF(Q31<=80,5,0)))+IF(R31>=50,10,IF(R31>=40,6,IF(R31>=30,3,0)))+IF(S31>=45,15,IF(S31>=40,12,IF(S31>=35,8,IF(S31>=30,4,0))))+IF(T31>=10000,10,IF(T31>=8000,7,IF(T31>=6000,4,0)))+IF(U31<>"",U31*5,0)+IF(V31<>"",V31*10,0)+IF(W31<>"",W31*8,0)+IF(X31>=66,10,IF(X31>=50,6,IF(X31>=33,3,0))) | AP31: =IF(AA31=1,5,0)+IF(AB31=1,5,0)+IF(AC31=1,5,0)+IF(AD31=1,5,0)+IF(AE31=1,5,0)+IF(AF31=1,5,0) | AQ31: =IF(AG31<>"",AG31*8,0)+IF(AH31<>"",AH31*5,0)+IF(AI31<>"",AI31*10,0)+IF(AJ31<>"",AJ31*3,0)+IF(AK31=1,5,0)+IF(AL31<>"",AL31*5,0) | AR31: =AM31+AN31+AO31+AP31+AQ31

Sheet Mar 2026
A1: Info | C1: 🕌 Prayers | I1: 💉 Glucose | O1: ⏱️ Whoop Age | AA1: 👨‍👩‍👧‍👦 Family | AG1: ✨ Habits | AM1: 📊 Scores
A2: Day | B2: Date | C2: Fajr | D2: Dhuhr | E2: Asr | F2: Maghrib | G2: Isha | H2: 📖 Quran | I2: Avg | J2: TIR% | K2: CV% | L2: Hypos | M2: Insulin | N2: NoP | O2: Sleep | P2: Consist | Q2: RHR | R2: HRV | S2: VO2 | T2: Steps | U2: Zone1-3 | V2: Zone4-5 | W2: Strength | X2: Recovery | Y2: Strain | Z2: Age | AA2: 👩 Mom | AB2: 👨 Dad | AC2: 👧 Jana | AD2: 👶 Tia | AE2: 👦 Ahmed | AF2: 👩‍🦱 Eman | AG2: 🏋️ | AH2: 📚 | AI2: 🧘 | AJ2: 💧 | AK2: 💊 | AL2: 🦷 | AM2: Prayer | AN2: Health | AO2: Whoop | AP2: Family | AQ2: Habit | AR2: TOTAL
AA3: (5 pts) | AB3: (5 pts) | AC3: (5 pts) | AD3: (5 pts) | AE3: (5 pts) | AF3: (5 pts)
A4: 1 | B4: Sun | AM4: =SUMPRODUCT((TRUNC(C4:G4))*10)+SUMPRODUCT(ROUND((C4:G4-TRUNC(C4:G4))*10,0)*5)+IF(H4="",0,H4*10) | AN4: =IF(AND(I4>=70,I4<=140),20,IF(AND(I4>140,I4<=180),10,0))+IF(J4>=70,15,IF(J4>=50,8,0))+IF(AND(K4>0,K4<=30),10,IF(AND(K4>30,K4<=50),5,0))+IF(L4=0,10,0)+IF(M4>0,5,0)+IF(N4<>"",N4*2,0) | AO4: =IF(AND(O4>=7,O4<=8),15,IF(AND(O4>=6,O4<7),8,IF(O4>8,10,0)))+IF(P4>=80,10,IF(P4>=70,6,IF(P4>=60,3,0)))+IF(Q4<=60,15,IF(Q4<=70,10,IF(Q4<=80,5,0)))+IF(R4>=50,10,IF(R4>=40,6,IF(R4>=30,3,0)))+IF(S4>=45,15,IF(S4>=40,12,IF(S4>=35,8,IF(S4>=30,4,0))))+IF(T4>=10000,10,IF(T4>=8000,7,IF(T4>=6000,4,0)))+IF(U4<>"",U4*5,0)+IF(V4<>"",V4*10,0)+IF(W4<>"",W4*8,0)+IF(X4>=66,10,IF(X4>=50,6,IF(X4>=33,3,0))) | AP4: =IF(AA4=1,5,0)+IF(AB4=1,5,0)+IF(AC4=1,5,0)+IF(AD4=1,5,0)+IF(AE4=1,5,0)+IF(AF4=1,5,0) | AQ4: =IF(AG4<>"",AG4*8,0)+IF(AH4<>"",AH4*5,0)+IF(AI4<>"",AI4*10,0)+IF(AJ4<>"",AJ4*3,0)+IF(AK4=1,5,0)+IF(AL4<>"",AL4*5,0) | AR4: =AM4+AN4+AO4+AP4+AQ4
A5: 2 | B5: Mon | AM5: =SUMPRODUCT((TRUNC(C5:G5))*10)+SUMPRODUCT(ROUND((C5:G5-TRUNC(C5:G5))*10,0)*5)+IF(H5="",0,H5*10) | AN5: =IF(AND(I5>=70,I5<=140),20,IF(AND(I5>140,I5<=180),10,0))+IF(J5>=70,15,IF(J5>=50,8,0))+IF(AND(K5>0,K5<=30),10,IF(AND(K5>30,K5<=50),5,0))+IF(L5=0,10,0)+IF(M5>0,5,0)+IF(N5<>"",N5*2,0) | AO5: =IF(AND(O5>=7,O5<=8),15,IF(AND(O5>=6,O5<7),8,IF(O5>8,10,0)))+IF(P5>=80,10,IF(P5>=70,6,IF(P5>=60,3,0)))+IF(Q5<=60,15,IF(Q5<=70,10,IF(Q5<=80,5,0)))+IF(R5>=50,10,IF(R5>=40,6,IF(R5>=30,3,0)))+IF(S5>=45,15,IF(S5>=40,12,IF(S5>=35,8,IF(S5>=30,4,0))))+IF(T5>=10000,10,IF(T5>=8000,7,IF(T5>=6000,4,0)))+IF(U5<>"",U5*5,0)+IF(V5<>"",V5*10,0)+IF(W5<>"",W5*8,0)+IF(X5>=66,10,IF(X5>=50,6,IF(X5>=33,3,0))) | AP5: =IF(AA5=1,5,0)+IF(AB5=1,5,0)+IF(AC5=1,5,0)+IF(AD5=1,5,0)+IF(AE5=1,5,0)+IF(AF5=1,5,0) | AQ5: =IF(AG5<>"",AG5*8,0)+IF(AH5<>"",AH5*5,0)+IF(AI5<>"",AI5*10,0)+IF(AJ5<>"",AJ5*3,0)+IF(AK5=1,5,0)+IF(AL5<>"",AL5*5,0) | AR5: =AM5+AN5+AO5+AP5+AQ5
A6: 3 | B6: Tue | AM6: =SUMPRODUCT((TRUNC(C6:G6))*10)+SUMPRODUCT(ROUND((C6:G6-TRUNC(C6:G6))*10,0)*5)+IF(H6="",0,H6*10) | AN6: =IF(AND(I6>=70,I6<=140),20,IF(AND(I6>140,I6<=180),10,0))+IF(J6>=70,15,IF(J6>=50,8,0))+IF(AND(K6>0,K6<=30),10,IF(AND(K6>30,K6<=50),5,0))+IF(L6=0,10,0)+IF(M6>0,5,0)+IF(N6<>"",N6*2,0) | AO6: =IF(AND(O6>=7,O6<=8),15,IF(AND(O6>=6,O6<7),8,IF(O6>8,10,0)))+IF(P6>=80,10,IF(P6>=70,6,IF(P6>=60,3,0)))+IF(Q6<=60,15,IF(Q6<=70,10,IF(Q6<=80,5,0)))+IF(R6>=50,10,IF(R6>=40,6,IF(R6>=30,3,0)))+IF(S6>=45,15,IF(S6>=40,12,IF(S6>=35,8,IF(S6>=30,4,0))))+IF(T6>=10000,10,IF(T6>=8000,7,IF(T6>=6000,4,0)))+IF(U6<>"",U6*5,0)+IF(V6<>"",V6*10,0)+IF(W6<>"",W6*8,0)+IF(X6>=66,10,IF(X6>=50,6,IF(X6>=33,3,0))) | AP6: =IF(AA6=1,5,0)+IF(AB6=1,5,0)+IF(AC6=1,5,0)+IF(AD6=1,5,0)+IF(AE6=1,5,0)+IF(AF6=1,5,0) | AQ6: =IF(AG6<>"",AG6*8,0)+IF(AH6<>"",AH6*5,0)+IF(AI6<>"",AI6*10,0)+IF(AJ6<>"",AJ6*3,0)+IF(AK6=1,5,0)+IF(AL6<>"",AL6*5,0) | AR6: =AM6+AN6+AO6+AP6+AQ6
A7: 4 | B7: Wed | AM7: =SUMPRODUCT((TRUNC(C7:G7))*10)+SUMPRODUCT(ROUND((C7:G7-TRUNC(C7:G7))*10,0)*5)+IF(H7="",0,H7*10) | AN7: =IF(AND(I7>=70,I7<=140),20,IF(AND(I7>140,I7<=180),10,0))+IF(J7>=70,15,IF(J7>=50,8,0))+IF(AND(K7>0,K7<=30),10,IF(AND(K7>30,K7<=50),5,0))+IF(L7=0,10,0)+IF(M7>0,5,0)+IF(N7<>"",N7*2,0) | AO7: =IF(AND(O7>=7,O7<=8),15,IF(AND(O7>=6,O7<7),8,IF(O7>8,10,0)))+IF(P7>=80,10,IF(P7>=70,6,IF(P7>=60,3,0)))+IF(Q7<=60,15,IF(Q7<=70,10,IF(Q7<=80,5,0)))+IF(R7>=50,10,IF(R7>=40,6,IF(R7>=30,3,0)))+IF(S7>=45,15,IF(S7>=40,12,IF(S7>=35,8,IF(S7>=30,4,0))))+IF(T7>=10000,10,IF(T7>=8000,7,IF(T7>=6000,4,0)))+IF(U7<>"",U7*5,0)+IF(V7<>"",V7*10,0)+IF(W7<>"",W7*8,0)+IF(X7>=66,10,IF(X7>=50,6,IF(X7>=33,3,0))) | AP7: =IF(AA7=1,5,0)+IF(AB7=1,5,0)+IF(AC7=1,5,0)+IF(AD7=1,5,0)+IF(AE7=1,5,0)+IF(AF7=1,5,0) | AQ7: =IF(AG7<>"",AG7*8,0)+IF(AH7<>"",AH7*5,0)+IF(AI7<>"",AI7*10,0)+IF(AJ7<>"",AJ7*3,0)+IF(AK7=1,5,0)+IF(AL7<>"",AL7*5,0) | AR7: =AM7+AN7+AO7+AP7+AQ7
